Workbook

Sheet PRODUTOS
A1: IMAGEM | B1: CÓDIGO DO PRODUTO | C1: DESCRIÇÃO | D1: REFERÊNCIA DO FABRICANTE | E1: MARCA | F1: INFORMAÇÕES COMPLEMENTARES DO FORNECEDOR | G1: CATEGORIA | H1: ARQUIVO IMAGEM (SITE / CATÁLOGO) | I1: POST INSTAGRAM | J1: TRATAMENTO DA IMAGEM | K1: ALERTAS / CONFERIR | L1: ORIGEM
B2: 55026 | C2: QUADRO PAINEL PARA COMANDO 20X20X12 | F2: Quadro de comando metálico com porta, fechadura e placa de montagem interna (laranja). Medidas A x L x P (cm) indicadas na descrição. | G2: Elétrica / Comandos | H2: 55026.png | I2: QUADRO-PAINEL-PARA-COMANDO.jpg | J2: Recorte original do catálogo + ampliação IA 4x | L2: Catálogo pág. 2
B3: 55027 | C3: QUADRO PAINEL PARA COMANDO 30X20X20 | F3: Quadro de comando metálico com porta, fechadura e placa de montagem interna (laranja). Medidas A x L x P (cm) indicadas na descrição. | G3: Elétrica / Comandos | H3: 55027.png | I3: QUADRO-PAINEL-PARA-COMANDO.jpg | J3: Recorte original do catálogo + ampliação IA 4x | L3: Catálogo pág. 2
B4: 55029 | C4: QUADRO PAINEL PARA COMANDO 40X30X20 | F4: Quadro de comando metálico com porta, fechadura e placa de montagem interna (laranja). Medidas A x L x P (cm) indicadas na descrição. | G4: Elétrica / Comandos | H4: 55029.png | I4: QUADRO-PAINEL-PARA-COMANDO.jpg | J4: Recorte original do catálogo + ampliação IA 4x | L4: Catálogo pág. 2
B5: 55028 | C5: QUADRO PAINEL PARA COMANDO 40X30X25 | F5: Quadro de comando metálico com porta, fechadura e placa de montagem interna (laranja). Medidas A x L x P (cm) indicadas na descrição. | G5: Elétrica / Comandos | H5: 55028.png | I5: QUADRO-PAINEL-PARA-COMANDO.jpg | J5: Recorte original do catálogo + ampliação IA 4x | L5: Catálogo pág. 2
B6: 55030 | C6: QUADRO PAINEL PARA COMANDO 60X40X20 | F6: Quadro de comando metálico com porta, fechadura e placa de montagem interna (laranja). Medidas A x L x P (cm) indicadas na descrição. | G6: Elétrica / Comandos | H6: 55030.png | I6: QUADRO-PAINEL-PARA-COMANDO.jpg | J6: Recorte original do catálogo + ampliação IA 4x | L6: Catálogo pág. 2
B7: 55031 | C7: QUADRO PAINEL PARA COMANDO 60X40X25 | F7: Quadro de comando metálico com porta, fechadura e placa de montagem interna (laranja). Medidas A x L x P (cm) indicadas na descrição. | G7: Elétrica / Comandos | H7: 55031.png | I7: QUADRO-PAINEL-PARA-COMANDO.jpg | J7: Recorte original do catálogo + ampliação IA 4x | L7: Catálogo pág. 2
B8: 55032 | C8: QUADRO PAINEL PARA COMANDO 60X60X20 | F8: Quadro de comando metálico com porta, fechadura e placa de montagem interna (laranja). Medidas A x L x P (cm) indicadas na descrição. | G8: Elétrica / Comandos | H8: 55032.png | I8: QUADRO-PAINEL-PARA-COMANDO.jpg | J8: Recorte original do catálogo + ampliação IA 4x | L8: Catálogo pág. 2
B9: 55033 | C9: QUADRO PAINEL PARA COMANDO 60X60X25 | F9: Quadro de comando metálico com porta, fechadura e placa de montagem interna (laranja). Medidas A x L x P (cm) indicadas na descrição. | G9: Elétrica / Comandos | H9: 55033.png | I9: QUADRO-PAINEL-PARA-COMANDO.jpg | J9: Recorte original do catálogo + ampliação IA 4x | L9: Catálogo pág. 2
B10: 55034 | C10: QUADRO PAINEL PARA COMANDO 80X60X25 | F10: Quadro de comando metálico com porta, fechadura e placa de montagem interna (laranja). Medidas A x L x P (cm) indicadas na descrição. | G10: Elétrica / Comandos | H10: 55034.png | I10: QUADRO-PAINEL-PARA-COMANDO.jpg | J10: Recorte original do catálogo + ampliação IA 4x | L10: Catálogo pág. 2
B11: 54752 | C11: MALA COMPACTA PARA FERRAMENTAS FACON | D11: BS006 | E11: FACON | F11: Dimensões 31 x 20 x 24 cm. Alça para transporte reforçada. | G11: Ferramentas / Instrumentos | H11: 54752.png | I11: 54752_MALA-COMPACTA-PARA-FERRAMENTAS-FACON.jpg | J11: Fundo removido (IA ISNet + máscara por cor do fundo) + ampliação IA 4x | L11: Catálogo pág. 2
B12: 54753 | C12: MALA PARA FERRAMENTAS C FUNDO REFORÇADO FACON | D12: BS008 | E12: FACON | F12: Dimensões 43 x 27 x 28 cm. Fundo resistente, alça removível. | G12: Ferramentas / Instrumentos | H12: 54753.png | I12: 54753_MALA-PARA-FERRAMENTAS-C-FUNDO-REFORCADO-FACON.jpg | J12: Fundo removido (IA ISNet + máscara por cor do fundo) + ampliação IA 4x | L12: Catálogo pág. 2
B13: 54755 | C13: MALA PARA FERRAMENTAS C/ ALÇA INOX BIG PLUS FACON | D13: BS009 | E13: FACON | F13: Medidas no catálogo: 230 x 360 x 230 (indicado em cm; provavelmente mm). Alça em inox. | G13: Ferramentas / Instrumentos | H13: 54755.png | I13: 54755_MALA-PARA-FERRAMENTAS-C-ALCA-INOX-BIG-PLUS-FACON.jpg | J13: Fundo removido (IA ISNet + máscara por cor do fundo) + ampliação IA 4x | K13: Descrição corrigida (ALCA → ALÇA). | Medidas no catálogo 230 x 360 x 230 'cm' — provavelmente mm. Conferir antes de publicar. | L13: Catálogo pág. 2
B14: 54756 | C14: MOCHILA PARA FERRAMENTAS SEM ESTOJO FACON | E14: FACON | F14: Mochila para ferramentas com bolsos externos, sem estojo interno. | G14: Ferramentas / Instrumentos | H14: 54756.png | I14: 54756_MOCHILA-PARA-FERRAMENTAS-SEM-ESTOJO-FACON.jpg | J14: Fundo removido (IA ISNet + máscara por cor do fundo) + ampliação IA 4x | L14: Catálogo pág. 2
B15: 54760 | C15: MALA FIT PARA FERRAMENTAS FACON | D15: 4648 | E15: FACON | F15: Dimensões 43 x 27 x 28 cm. | G15: Ferramentas / Instrumentos | H15: 54760.png | I15: 54760_MALA-FIT-PARA-FERRAMENTAS-FACON.jpg | J15: Fundo removido (IA ISNet + máscara por cor do fundo) + ampliação IA 4x | L15: Catálogo pág. 2
B16: S/ CÓDIGO | C16: LUVA ANTICORTE WORKER WK31 | D16: WK31 | E16: WORKER | F16: Luva de proteção anticorte com banho na palma. | G16: EPI / Segurança | H16: SEM-CODIGO_LUVA-ANTICORTE-WORKER-WK31.png | I16: LUVA-ANTICORTE-WORKER-WK31.jpg | J16: Recorte original do catálogo + ampliação IA 4x | K16: Produto sem código no catálogo — informar código do sistema. | L16: Catálogo PDF
B17: S/ CÓDIGO | C17: LUVA POLIÉSTER BANHO PU VE702PG | D17: VE702PG | E17: DELTA PLUS | F17: Luva de poliéster com banho de poliuretano (PU) na palma, boa sensibilidade para montagem. Marca identificada pelo logo na foto. | G17: EPI / Segurança | H17: SEM-CODIGO_LUVA-POLIESTER-BANHO-PU-VE702PG.png | I17: LUVA-POLIESTER-BANHO-PU-VE702PG.jpg | J17: Recorte original do catálogo + ampliação IA 4x | K17: Produto sem código no catálogo — informar código do sistema. | L17: Catálogo PDF
B18: S/ CÓDIGO | C18: LUVA NITRÍLICA 33 CM NITREX VE801 | D18: VE801 | F18: Luva nitrílica de cano longo (33 cm) para manuseio de produtos químicos. | G18: EPI / Segurança | H18: SEM-CODIGO_LUVA-NITRILICA-33-CM-NITREX-VE801.png | I18: LUVA-NITRILICA-33-CM-NITREX-VE801.jpg | J18: Recorte original do catálogo + ampliação IA 4x | K18: Produto sem código no catálogo — informar código do sistema. | L18: Catálogo PDF
B19: S/ CÓDIGO | C19: ÓCULOS PROTEÇÃO UVA UVB SKY | D19: SKY | F19: Óculos de segurança com proteção UVA/UVB, lente escura (verde). | G19: EPI / Segurança | H19: SEM-CODIGO_OCULOS-PROTECAO-UVA-UVB-SKY.png | I19: OCULOS-PROTECAO-UVA-UVB-SKY.jpg | J19: Recorte original do catálogo + ampliação IA 4x | K19: Produto sem código no catálogo — informar código do sistema. | L19: Catálogo PDF
B20: S/ CÓDIGO | C20: ÓCULOS PROTEÇÃO UVA UVB SUMMER | D20: SUMMER | F20: Óculos de segurança com proteção UVA/UVB, lente incolor. | G20: EPI / Segurança | H20: SEM-CODIGO_OCULOS-PROTECAO-UVA-UVB-SUMMER.png | I20: OCULOS-PROTECAO-UVA-UVB-SUMMER.jpg | J20: Recorte original do catálogo + ampliação IA 4x | K20: Produto sem código no catálogo — informar código do sistema. | L20: Catálogo PDF
B21: 54824 | C21: SAPATO ELÁSTICO BRANCO SEM BICO MONO TPB100 38 CARTON | D21: TPB100 | E21: CARTON | F21: Sapato ocupacional branco com elástico lateral, sem biqueira. Numeração ao final da descrição. | G21: EPI / Segurança | H21: 54824.png | I21: SAPATO-ELASTICO-S-BICO-TPB100.jpg | J21: Recorte original do catálogo + ampliação IA 4x | L21: Catálogo pág. 3
B22: 54825 | C22: SAPATO ELÁSTICO BRANCO SEM BICO MONO TPB100 39 CARTON | D22: TPB100 | E22: CARTON | F22: Sapato ocupacional branco com elástico lateral, sem biqueira. Numeração ao final da descrição. | G22: EPI / Segurança | H22: 54825.png | I22: SAPATO-ELASTICO-S-BICO-TPB100.jpg | J22: Recorte original do catálogo + ampliação IA 4x | L22: Catálogo pág. 3
B23: 54826 | C23: SAPATO ELÁSTICO BRANCO SEM BICO MONO TPB100 40 CARTON | D23: TPB100 | E23: CARTON | F23: Sapato ocupacional branco com elástico lateral, sem biqueira. Numeração ao final da descrição. | G23: EPI / Segurança | H23: 54826.png | I23: SAPATO-ELASTICO-S-BICO-TPB100.jpg | J23: Recorte original do catálogo + ampliação IA 4x | L23: Catálogo pág. 3
B24: 54827 | C24: SAPATO ELÁSTICO BRANCO SEM BICO MONO TPB100 41 CARTON | D24: TPB100 | E24: CARTON | F24: Sapato ocupacional branco com elástico lateral, sem biqueira. Numeração ao final da descrição. | G24: EPI / Segurança | H24: 54827.png | I24: SAPATO-ELASTICO-S-BICO-TPB100.jpg | J24: Recorte original do catálogo + ampliação IA 4x | L24: Catálogo pág. 3
B25: 54828 | C25: SAPATO ELÁSTICO BRANCO SEM BICO MONO TPB100 42 CARTON | D25: TPB100 | E25: CARTON | F25: Sapato ocupacional branco com elástico lateral, sem biqueira. Numeração ao final da descrição. | G25: EPI / Segurança | H25: 54828.png | I25: SAPATO-ELASTICO-S-BICO-TPB100.jpg | J25: Recorte original do catálogo + ampliação IA 4x | L25: Catálogo pág. 3
B26: 54829 | C26: SAPATO ELÁSTICO BRANCO SEM BICO MONO TPB100 43 CARTON | D26: TPB100 | E26: CARTON | F26: Sapato ocupacional branco com elástico lateral, sem biqueira. Numeração ao final da descrição. | G26: EPI / Segurança | H26: 54829.png | I26: SAPATO-ELASTICO-S-BICO-TPB100.jpg | J26: Recorte original do catálogo + ampliação IA 4x | L26: Catálogo pág. 3
B27: 54830 | C27: SAPATO ELÁSTICO BRANCO SEM BICO MONO TPB100 44 CARTON | D27: TPB100 | E27: CARTON | F27: Sapato ocupacional branco com elástico lateral, sem biqueira. Numeração ao final da descrição. | G27: EPI / Segurança | H27: 54830.png | I27: SAPATO-ELASTICO-S-BICO-TPB100.jpg | J27: Recorte original do catálogo + ampliação IA 4x | L27: Catálogo pág. 3
B28: 54838 | C28: SAPATO POLIMÉRICO BRANCO SEM BICO BIDENCID COB101 36 CARTON | D28: COB101 | E28: CARTON | F28: Sapato polimérico branco, sem biqueira, fácil de lavar. Numeração ao final da descrição. | G28: EPI / Segurança | H28: 54838.png | I28: SAPATO-BRANCO-SEM-BICO-COB-101.jpg | J28: Recorte original do catálogo + ampliação IA 4x | K28: Descrição corrigida (POLIMERICO → POLIMÉRICO). | L28: Catálogo pág. 3
B29: 54839 | C29: SAPATO POLIMÉRICO BRANCO SEM BICO BIDENCID COB101 37 CARTON | D29: COB101 | E29: CARTON | F29: Sapato polimérico branco, sem biqueira, fácil de lavar. Numeração ao final da descrição. | G29: EPI / Segurança | H29: 54839.png | I29: SAPATO-BRANCO-SEM-BICO-COB-101.jpg | J29: Recorte original do catálogo + ampliação IA 4x | K29: Descrição corrigida (POLIMERICO → POLIMÉRICO). | L29: Catálogo pág. 3
B30: 54840 | C30: SAPATO POLIMÉRICO BRANCO SEM BICO BIDENCID COB101 38 CARTON | D30: COB101 | E30: CARTON | F30: Sapato polimérico branco, sem biqueira, fácil de lavar. Numeração ao final da descrição. | G30: EPI / Segurança | H30: 54840.png | I30: SAPATO-BRANCO-SEM-BICO-COB-101.jpg | J30: Recorte original do catálogo + ampliação IA 4x | K30: Descrição corrigida (POLIMERICO → POLIMÉRICO). | L30: Catálogo pág. 3
B31: 54841 | C31: SAPATO POLIMÉRICO BRANCO SEM BICO BIDENCID COB101 39 CARTON | D31: COB101 | E31: CARTON | F31: Sapato polimérico branco, sem biqueira, fácil de lavar. Numeração ao final da descrição. | G31: EPI / Segurança | H31: 54841.png | I31: SAPATO-BRANCO-SEM-BICO-COB-101.jpg | J31: Recorte original do catálogo + ampliação IA 4x | K31: Descrição corrigida (POLIMERICO → POLIMÉRICO). | L31: Catálogo pág. 3
B32: 54842 | C32: SAPATO POLIMÉRICO BRANCO SEM BICO BIDENCID COB101 40 CARTON | D32: COB101 | E32: CARTON | F32: Sapato polimérico branco, sem biqueira, fácil de lavar. Numeração ao final da descrição. | G32: EPI / Segurança | H32: 54842.png | I32: SAPATO-BRANCO-SEM-BICO-COB-101.jpg | J32: Recorte original do catálogo + ampliação IA 4x | K32: Descrição corrigida (POLIMERICO → POLIMÉRICO). | L32: Catálogo pág. 3
B33: 54843 | C33: SAPATO POLIMÉRICO BRANCO SEM BICO BIDENCID COB101 41 CARTON | D33: COB101 | E33: CARTON | F33: Sapato polimérico branco, sem biqueira, fácil de lavar. Numeração ao final da descrição. | G33: EPI / Segurança | H33: 54843.png | I33: SAPATO-BRANCO-SEM-BICO-COB-101.jpg | J33: Recorte original do catálogo + ampliação IA 4x | K33: Descrição corrigida (POLIMERICO → POLIMÉRICO). | L33: Catálogo pág. 3
B34: 54844 | C34: SAPATO POLIMÉRICO BRANCO SEM BICO BIDENCID COB101 42 CARTON | D34: COB101 | E34: CARTON | F34: Sapato polimérico branco, sem biqueira, fácil de lavar. Numeração ao final da descrição. | G34: EPI / Segurança | H34: 54844.png | I34: SAPATO-BRANCO-SEM-BICO-COB-101.jpg | J34: Recorte original do catálogo + ampliação IA 4x | K34: Descrição corrigida (POLIMERICO → POLIMÉRICO). | L34: Catálogo pág. 3
B35: 54120 | C35: CAPACITOR SIMPLES CBB60 5UF+-5%X250V | D35: CBB60 | E35: FACON | F35: Capacitor de funcionamento (permanente) CBB60, 250 VAC, tolerância ±5%, 50/60 Hz, terminais tipo faston. Uso em motores monofásicos (ventiladores, bombas, lavadoras). | G35: Capacitores | H35: 54120.png | I35: CAPACITOR-SIMPLES-250V-CBB60.jpg | J35: Recorte original do catálogo + ampliação IA 4x | L35: Catálogo pág. 3
B36: 55201 | C36: CAPACITOR SIMPLES CBB60 8UF+-5%X250V | D36: CBB60 | E36: FACON | F36: Capacitor de funcionamento (permanente) CBB60, 250 VAC, tolerância ±5%, 50/60 Hz, terminais tipo faston. Uso em motores monofásicos (ventiladores, bombas, lavadoras). | G36: Capacitores | H36: 55201.png | I36: CAPACITOR-SIMPLES-250V-CBB60.jpg | J36: Recorte original do catálogo + ampliação IA 4x | L36: Catálogo pág. 3
B37: 53140 | C37: CAPACITOR SIMPLES CBB60 10UF +-5% X 250V | D37: CBB60 | E37: FACON | F37: Capacitor de funcionamento (permanente) CBB60, 250 VAC, tolerância ±5%, 50/60 Hz, terminais tipo faston. Uso em motores monofásicos (ventiladores, bombas, lavadoras). | G37: Capacitores | H37: 53140.png | I37: CAPACITOR-SIMPLES-250V-CBB60.jpg | J37: Recorte original do catálogo + ampliação IA 4x | K37: Mesma descrição do(s) código(s) 53122: possível cadastro duplicado. | L37: Catálogo pág. 3
B38: 53122 | C38: CAPACITOR SIMPLES CBB60 10UF+-5%X250V | D38: CBB60 | E38: FACON | F38: Capacitor de funcionamento (permanente) CBB60, 250 VAC, tolerância ±5%, 50/60 Hz, terminais tipo faston. Uso em motores monofásicos (ventiladores, bombas, lavadoras). | G38: Capacitores | H38: 53122_CAPACITOR-SIMPLES-CBB60-10UF-5-X250V.png | I38: CAPACITOR-SIMPLES-250V-CBB60.jpg | J38: Recorte original do catálogo + ampliação IA 4x | K38: CÓDIGO REPETIDO no catálogo para produto diferente: CAPACITOR SIMPLES CBB65 10UF +-5%X440V | Mesma descrição do(s) código(s) 53140: possível cadastro duplicado. | L38: Catálogo pág. 3
B39: 55202 | C39: CAPACITOR SIMPLES CBB60 12UF +-5% X 250V | D39: CBB60 | E39: FACON | F39: Capacitor de funcionamento (permanente) CBB60, 250 VAC, tolerância ±5%, 50/60 Hz, terminais tipo faston. Uso em motores monofásicos (ventiladores, bombas, lavadoras). | G39: Capacitores | H39: 55202.png | I39: CAPACITOR-SIMPLES-250V-CBB60.jpg | J39: Recorte original do catálogo + ampliação IA 4x | L39: Catálogo pág. 3
B40: 54104 | C40: CAPACITOR SIMPLES CBB60 15UF +-5% X 250V | D40: CBB60 | E40: FACON | F40: Capacitor de funcionamento (permanente) CBB60, 250 VAC, tolerância ±5%, 50/60 Hz, terminais tipo faston. Uso em motores monofásicos (ventiladores, bombas, lavadoras). | G40: Capacitores | H40: 54104.png | I40: CAPACITOR-SIMPLES-250V-CBB60.jpg | J40: Recorte original do catálogo + ampliação IA 4x | L40: Catálogo pág. 3
...

Sheet ALERTAS CADASTRO
A1: CÓDIGO | B1: DESCRIÇÃO | C1: TIPO | D1: ALERTA / O QUE CONFERIR
A2: 52778 | B2: CAPACITOR DUPLO CBB65 25UF+10UF X 440VAC | C2: Código repetido | D2: CÓDIGO REPETIDO no catálogo para produto diferente: CAPACITOR DUPLO CBB65 35UF+6UF X 440VAC
A3: 52778 | B3: CAPACITOR DUPLO CBB65 35UF+6UF X 440VAC | C3: Código repetido | D3: CÓDIGO REPETIDO no catálogo para produto diferente: CAPACITOR DUPLO CBB65 25UF+10UF X 440VAC
A4: 52787 | B4: CAPACITOR DUPLO CBB65 25UF+1.5UF X 440VAC | C4: Código repetido | D4: CÓDIGO REPETIDO no catálogo para produto diferente: CAPACITOR DUPLO CBB65 25UF+ 10UF X 440VAC
A5: 52787 | B5: CAPACITOR DUPLO CBB65 25UF+ 10UF X 440VAC | C5: Código repetido | D5: CÓDIGO REPETIDO no catálogo para produto diferente: CAPACITOR DUPLO CBB65 25UF+1.5UF X 440VAC
A6: 52796 | B6: CAPACITOR DUPLO CBB65 30UF +3UF X 440VAC | C6: Código repetido | D6: CÓDIGO REPETIDO no catálogo para produto diferente: CAPACITOR DUPLO CBB65 30UF+ 12UF X 440VAC
A7: 52796 | B7: CAPACITOR DUPLO CBB65 30UF+ 12UF X 440VAC | C7: Código repetido | D7: CÓDIGO REPETIDO no catálogo para produto diferente: CAPACITOR DUPLO CBB65 30UF +3UF X 440VAC
A8: 52931 | B8: MULTÍMETRO DT-830B | C8: Código repetido | D8: CÓDIGO REPETIDO no catálogo para produto diferente: MULTÍMETRO My63 20KHZ FACON
A9: 52931 | B9: MULTÍMETRO My63 20KHZ FACON | C9: Código repetido | D9: CÓDIGO REPETIDO no catálogo para produto diferente: MULTÍMETRO DT-830B
A10: 53122 | B10: CAPACITOR SIMPLES CBB60 10UF+-5%X250V | C10: Código repetido | D10: CÓDIGO REPETIDO no catálogo para produto diferente: CAPACITOR SIMPLES CBB65 10UF +-5%X440V
A11: 53122 | B11: CAPACITOR SIMPLES CBB65 10UF +-5%X440V | C11: Código repetido | D11: CÓDIGO REPETIDO no catálogo para produto diferente: CAPACITOR SIMPLES CBB60 10UF+-5%X250V
A12: 53635 | B12: TERMOSTATO RC-15000-2 | C12: Código repetido | D12: CÓDIGO REPETIDO no catálogo para produto diferente: TERMOSTATO RC-45000-2
A13: 53635 | B13: TERMOSTATO RC-45000-2 | C13: Código repetido | D13: CÓDIGO REPETIDO no catálogo para produto diferente: TERMOSTATO RC-15000-2
... A36: 54165 | B36: TAMPA DA PINGADEIRA CINZA PURIFICADOR R600 IBBL | C36: Possível cadastro duplicado | D36: Mesma descrição do(s) código(s) 54166: possível cadastro duplicado.
A37: S/ CÓDIGO | B37: KTM 1000 (PEÇA PLÁSTICA BRANCA) | C37: Conferir informação | D37: Produto não identificado pela imagem; confirmar descrição.
A38: 50 | B38: MOLA P/ CURVAR TUBO 1/2 | C38: Conferir informação | D38: Código muito curto (50). Conferir se é o código correto no sistema.
A39: 52307 | B39: CONTATOR MAGNÉTICO 220V 20A ROHS | C39: Conferir informação | D39: 'ROHS' é selo de conformidade, não marca. Marca não identificada no catálogo.
A40: 52771 | B40: CAPACITOR SIMPLES CBB65 59UF +-5%X440V | C40: Conferir informação | D40: Descrição diz 59UF — provável 50UF. Conferir.
A41: 53493 | B41: DRENO TRANSPARENTE UNIVERSAL P/ AR CONDICIONADOS | C41: Conferir informação | D41: No catálogo a descrição está igual à do 53794; título da seção: MANGUEIRA DE DRENAGEM 60CM.
A42: 53680 | B42: TERMOSTATO RC-4209-2 | C42: Conferir informação | D42: Seção do catálogo diz RFR 4009-2, descrição diz RC-4209-2. Conferir modelo.
A43: 53682 | B43: TERMOSTATO RC- 53600-2 | C43: Conferir informação | D43: Seção do catálogo diz RC-42600-2, mas a descrição diz RC-53600-2 (igual ao 53684). Conferir modelo.
A44: 53943 | B44: MANGUEIRA ESPECIAL 8 X 1,66MM PACOTE 2M | C44: Conferir informação | D44: Título da seção: MANGUEIRA GROSSA 9,52X1,60MM, mas a descrição repete a do 53945 (8 X 1,66MM). Conferir.
A45: 53953 | B45: TORNEIRA PARA BEBEDOURO ROSCA BRANCO E AZUL | C45: Conferir informação | D45: Descrição igual à do 53954 (ROSCA BRANCO E AZUL); título da seção: TORNEIRA PREMIUM.
A46: 54166 | B46: TAMPA DA PINGADEIRA CINZA PURIFICADOR R600 IBBL | C46: Conferir informação | D46: Título da seção: PINGADEIRA PLAST FUMÊ, mas a descrição repete a do 54165 (TAMPA CINZA). Conferir.
A47: 54755 | B47: MALA PARA FERRAMENTAS C/ ALÇA INOX BIG PLUS FACON | C47: Conferir informação | D47: Medidas no catálogo 230 x 360 x 230 'cm' — provavelmente mm. Conferir antes de publicar.
A48: 55021 | B48: RELÉ ELETRÔNICO DIGITAL FALTA DE FASE BVF-1P REF- BVS1-P | C48: Conferir informação | D48: Descrição cita BVF-1P, mas a referência é BVS1-P (falta e sequência de fase). Conferir.
A49: 55091 | B49: FILTRO DE LINHA CINZA BIVOLT 1,5M DE CABO MG-3001 | C49: Conferir informação | D49: No catálogo o título 'FILTRO DE LINHA MG-3001' aparece repetido sobre a foto dos DPS.
... A52: 58450 | B52: CABO FLEXÍVEL VERDE | C52: Conferir informação | D52: Código vindo do nome do arquivo PSD; conferir descrição/bitola.
A53: S/ CÓDIGO | B53: LUVA ANTICORTE WORKER WK31 | C53: Sem código | D53: Produto sem código no catálogo — informar código do sistema.
A54: S/ CÓDIGO | B54: LUVA POLIÉSTER BANHO PU VE702PG | C54: Sem código | D54: Produto sem código no catálogo — informar código do sistema.
A55: S/ CÓDIGO | B55: LUVA NITRÍLICA 33 CM NITREX VE801 | C55: Sem código | D55: Produto sem código no catálogo — informar código do sistema.
A56: S/ CÓDIGO | B56: ÓCULOS PROTEÇÃO UVA UVB SKY | C56: Sem código | D56: Produto sem código no catálogo — informar código do sistema.
A57: S/ CÓDIGO | B57: ÓCULOS PROTEÇÃO UVA UVB SUMMER | C57: Sem código | D57: Produto sem código no catálogo — informar código do sistema.
A58: S/ CÓDIGO | B58: SUPORTE PARA EVAPORADORA | C58: Sem código | D58: Produto sem código no catálogo — informar código do sistema.
A59: S/ CÓDIGO | B59: TUBO ESPONJOSO (TUBEX) | C59: Sem código | D59: Produto sem código no catálogo — informar código do sistema.
A60: S/ CÓDIGO | B60: TUBO DE COBRE | C60: Sem código | D60: Produto sem código no catálogo — informar código do sistema.
A61: S/ CÓDIGO | B61: FLUXO PRATA ARON 200 50GR | C61: Sem código | D61: Produto sem código no catálogo — informar código do sistema.
A62: S/ CÓDIGO | B62: MOTOR BLACK VENT REFR DOMEST 2 POLOS /BRE 43A /BRE 49 B | C62: Sem código | D62: Produto sem código no catálogo — informar código do sistema.
A63: S/ CÓDIGO | B63: MOTOR VENT ELETROLUX/BRASTEMP CONSUL/SAMSUNG | C63: Sem código | D63: Produto sem código no catálogo — informar código do sistema.
A64: S/ CÓDIGO | B64: RELÉ DE TEMPO RTDF 12H 60 MIN COEL | C64: Sem código | D64: Produto sem código no catálogo — informar código do sistema.
...

Sheet RESUMO
A1: CATEGORIA | B1: Nº DE ITENS | C1: ITENS COM ALERTA | D1: % COM ALERTA
A2: Automação / Temporizadores | B2: =COUNTIF(PRODUTOS!$G$2:$G$324,A2) -> 15 | C2: =COUNTIFS(PRODUTOS!$G$2:$G$324,A2,PRODUTOS!$K$2:$K$324,"?*") -> 5 | D2: =IF(B2=0,0,C2/B2) -> 0.33333333
A3: Capacitores | B3: =COUNTIF(PRODUTOS!$G$2:$G$324,A3) -> 95 | C3: =COUNTIFS(PRODUTOS!$G$2:$G$324,A3,PRODUTOS!$K$2:$K$324,"?*") -> 17 | D3: =IF(B3=0,0,C3/B3) -> 0.17894737
A4: EPI / Segurança | B4: =COUNTIF(PRODUTOS!$G$2:$G$324,A4) -> 21 | C4: =COUNTIFS(PRODUTOS!$G$2:$G$324,A4,PRODUTOS!$K$2:$K$324,"?*") -> 14 | D4: =IF(B4=0,0,C4/B4) -> 0.66666667
A5: Elétrica / Comandos | B5: =COUNTIF(PRODUTOS!$G$2:$G$324,A5) -> 68 | C5: =COUNTIFS(PRODUTOS!$G$2:$G$324,A5,PRODUTOS!$K$2:$K$324,"?*") -> 17 | D5: =IF(B5=0,0,C5/B5) -> 0.25
A6: Ferramentas / Instrumentos | B6: =COUNTIF(PRODUTOS!$G$2:$G$324,A6) -> 27 | C6: =COUNTIFS(PRODUTOS!$G$2:$G$324,A6,PRODUTOS!$K$2:$K$324,"?*") -> 11 | D6: =IF(B6=0,0,C6/B6) -> 0.40740741
A7: Filtros e Purificadores de Água | B7: =COUNTIF(PRODUTOS!$G$2:$G$324,A7) -> 18 | C7: =COUNTIFS(PRODUTOS!$G$2:$G$324,A7,PRODUTOS!$K$2:$K$324,"?*") -> 8 | D7: =IF(B7=0,0,C7/B7) -> 0.44444444
A8: Instalação de Ar-Condicionado | B8: =COUNTIF(PRODUTOS!$G$2:$G$324,A8) -> 8 | C8: =COUNTIFS(PRODUTOS!$G$2:$G$324,A8,PRODUTOS!$K$2:$K$324,"?*") -> 6 | D8: =IF(B8=0,0,C8/B8) -> 0.75
A9: Peças para Lavadora e Bebedouro | B9: =COUNTIF(PRODUTOS!$G$2:$G$324,A9) -> 8 | C9: =COUNTIFS(PRODUTOS!$G$2:$G$324,A9,PRODUTOS!$K$2:$K$324,"?*") -> 2 | D9: =IF(B9=0,0,C9/B9) -> 0.25
A10: Químicos / Solda e Vedação | B10: =COUNTIF(PRODUTOS!$G$2:$G$324,A10) -> 14 | C10: =COUNTIFS(PRODUTOS!$G$2:$G$324,A10,PRODUTOS!$K$2:$K$324,"?*") -> 1 | D10: =IF(B10=0,0,C10/B10) -> 0.071428571
A11: Refrigeração / Componentes | B11: =COUNTIF(PRODUTOS!$G$2:$G$324,A11) -> 49 | C11: =COUNTIFS(PRODUTOS!$G$2:$G$324,A11,PRODUTOS!$K$2:$K$324,"?*") -> 17 | D11: =IF(B11=0,0,C11/B11) -> 0.34693878
A12: TOTAL | B12: =SUM(B2:B11) -> 323 | C12: =SUM(C2:C11) -> 98 | D12: =IF(B12=0,0,C12/B12) -> 0.30340557
A14: Itens sem código | B14: =COUNTIF(PRODUTOS!$B$2:$B$324,"S/ CÓDIGO") -> 19
A15: Imagens de produto distintas | B15: 145
A16: Posts de Instagram gerados | B16: 145
A17: Fonte: catálogo 'oficial_livro_paginas_impares.pdf' + imagens enviadas (fotos e PSD). Contagens de imagens/posts calculadas na geração do arquivo.

Sheet LEIA-ME
A1: O QUE É | B1: Base de produtos extraída do catálogo Aristeu Refrigeração (PDF) com foto tratada de cada item.
A2: IMAGEM | B2: Miniatura 30x30 px (clique na imagem para ver maior; ela foi inserida com resolução 4x para ficar nítida com zoom).
A3: ARQUIVO IMAGEM | B3: Nome do PNG 1200x1200 com fundo transparente na pasta imagens/png_transparente_1200 — pronto para o site e para montar catálogo. O nome do arquivo é o código do produto.
A4: POST INSTAGRAM | B4: Arte 1080x1350 (formato retrato 4:5) na pasta imagens/instagram_1080x1350 — um post por produto/família, com logo, códigos e WhatsApp das lojas.
A5: TRATAMENTO | B5: Fotos do catálogo ampliadas 4x por IA (Real-ESRGAN). Onde a foto não tinha recorte, o fundo foi removido por IA (ISNet). As fotos originais do catálogo são pequenas (≈100–400 px); para zoom de e-commerce acima de 1200 px, o ideal é pedir as fotos originais ao fornecedor.
A6: INFORMAÇÕES COMPLEMENTARES | B6: Dados do próprio catálogo (medidas, aplicações, compatibilidades, referências) + descrição técnica geral do tipo de produto. Conferir ficha técnica do fornecedor antes de publicar especificações críticas.
A7: ALERTAS / CONFERIR | B7: Problemas encontrados no catálogo: mesmo código usado para produtos diferentes, descrições trocadas, produtos sem código e correções de digitação. Ver aba ALERTAS CADASTRO — corrigir no sistema evita venda e compra do item errado.
A8: ITENS 'S/ CÓDIGO' | B8: Aparecem no catálogo ou nas imagens enviadas sem código. Preencher a coluna CÓDIGO com o código do sistema e renomear o arquivo PNG correspondente.
A9: COMO EDITAR | B9: Pode editar/preencher as colunas B a G livremente; a aba RESUMO recalcula sozinha.
