Workbook

Sheet PRODUTOS
A1: IMAGEM | B1: CÓDIGO DO PRODUTO | C1: DESCRIÇÃO | D1: REFERÊNCIA DO FABRICANTE | E1: MARCA / FABRICANTE | F1: INFORMAÇÕES COMPLEMENTARES DO FORNECEDOR | G1: SALDO | H1: STATUS DA FOTO | I1: CATEGORIA | J1: ARQUIVO IMAGEM (SITE / CATÁLOGO) | K1: POST INSTAGRAM | L1: DESCRIÇÃO NO CATÁLOGO | M1: DIVERGÊNCIAS / CONFERIR
B2: 055221 | C2: CONTROLADOR DIG TEMP P REFR CERVEJEIRA P03CG FAZ CJ COM B05G | D2: P03CGBARR-S-0FS-- | E2: COEL | F2: Controlador digital de temperatura para refrigerador/cervejeira. Faz conjunto com o sensor B05G (catálogo). | G2: 1 | H2: COM FOTO | I2: Automação / Temporizadores | J2: 055221.png | K2: 055221_CONTROLADOR-DIG-TEMP-P-REFR-CERVEJEIRA-P03CG-FAZ-C.jpg | L2: CONTROLADOR DIG TEMP P REFR CERVEJEIRA P03C COEL REF-P03CGBARR-S-0FS (FAZ CONJUNTO COM B05G)
B3: 054851 | C3: INTERRUP PROGRAMAVEL HORARIO DE ENERGIA RTM TEMPORIZADO COEL | D3: 11249014 | E3: COEL | F3: Interruptor horário programável analógico (timer) RTM para ligar/desligar cargas em horários definidos. | G3: 8 | H3: COM FOTO | I3: Automação / Temporizadores | J3: 054851.png | K3: 054851_INTERRUP-PROGRAMAVEL-HORARIO-DE-ENERGIA-RTM-TEMPOR.jpg | L3: INTERRUPTOR PROGRAMÁVEL HORÁRIO DE ENERGIA RTM TEMPORIZADO COEL REF- 11249014
B4: 054852 | C4: PROGRAMADOR HORA D ENERGIA RTST 20 MEMORIAS RTST-20HR-P COEL | D4: RTST-20HR-P | E4: COEL | F4: Programador horário digital com 20 memórias (RTST 20). | G4: 5 | H4: COM FOTO | I4: Automação / Temporizadores | J4: 054852.png | K4: 054852_PROGRAMADOR-HORA-D-ENERGIA-RTST-20-MEMORIAS-RTST-2.jpg | L4: PROGRAMADOR HORA DE ENERGIA RTM TEMPORIZADO REF- RTS-20HR-P COEL | M4: [Referência diferente] Planilha: RTST-20HR-P | Catálogo: RTS-20HR-P
B5: 054978 | C5: RELE DE TEMPO AEG-ALIM 12VCC 60 SEGUNDOS COEL | D5: AEG-FGS---P | E5: COEL | F5: Relé de tempo AG com alimentação 12 VCC, escala até 60 segundos. | G5: 6 | H5: COM FOTO | I5: Automação / Temporizadores | J5: 054978.png | K5: 054978_RELE-DE-TEMPO-AEG-ALIM-12VCC-60-SEGUNDOS-COEL.jpg | L5: RELÉ DE TEMPO AG-ALIM 12VCC 60 SEGUNDOS REF-AEG-FGS-P
B6: 054976 | C6: RELE DE TEMPO AEG-ALIM 94A 242VAC 30 SEGUNDOS COEL | D6: AEG-UFS---P | E6: COEL | F6: Relé de tempo AG, alimentação 94 a 242 VAC, escala até 30 segundos. | G6: 2 | H6: COM FOTO | I6: Automação / Temporizadores | J6: 054976.png | K6: 054976_RELE-DE-TEMPO-AEG-ALIM-94A-242VAC-30-SEGUNDOS-COEL.jpg | L6: RELÉ DE TEMPO AG-ALIM 94A 242VAC 30 SEGUNDOS REF-AEG-UFS-P
B7: 053494 | C7: CAPACITOR CBB60, 5UF +-5% X 250V COM FIO FACON | D7: CBB60 | E7: FACON | F7: Capacitor de funcionamento CBB60 com cabos (fios) de ligação, 250 VAC, tolerância ±5%, 50/60 Hz. Uso em motores monofásicos. | G7: 36 | H7: COM FOTO | I7: Capacitores | J7: 053494.png | K7: CAPACITOR-COM-FIO-250V-CBB60.jpg | L7: CAPACITOR CBB60 5UF +-5%X250V COM FIO | M7: [Referência vinda do catálogo] Referência vazia na planilha; usada a do catálogo: CBB60
B8: 054120 | C8: CAPACITOR CBB60, 5UF +-5% X 250V FACON | D8: CBB60 | E8: FACON | F8: Capacitor de funcionamento (permanente) CBB60, 250 VAC, tolerância ±5%, 50/60 Hz, terminais tipo faston. Uso em motores monofásicos (ventiladores, bombas, lavadoras). | G8: 18 | H8: COM FOTO | I8: Capacitores | J8: 054120.png | K8: CAPACITOR-SIMPLES-250V-CBB60.jpg | L8: CAPACITOR SIMPLES CBB60 5UF+-5%X250V | M8: [Referência vinda do catálogo] Referência vazia na planilha; usada a do catálogo: CBB60
B9: 053495 | C9: CAPACITOR CBB60, 6UF +-5% X 250V COM FIO FACON | D9: CBB60 | E9: FACON | F9: Capacitor de funcionamento CBB60 com cabos (fios) de ligação, 250 VAC, tolerância ±5%, 50/60 Hz. Uso em motores monofásicos. | G9: 90 | H9: COM FOTO | I9: Capacitores | J9: 053495.png | K9: CAPACITOR-COM-FIO-250V-CBB60.jpg | L9: CAPACITOR CBB60 6UF +-5%X250V COM FIO | M9: [Referência vinda do catálogo] Referência vazia na planilha; usada a do catálogo: CBB60
B10: 053496 | C10: CAPACITOR CBB60, 7UF +-5% X 250V COM FIO FACON | D10: CBB60 | E10: FACON | F10: Capacitor de funcionamento CBB60 com cabos (fios) de ligação, 250 VAC, tolerância ±5%, 50/60 Hz. Uso em motores monofásicos. | G10: 1 | H10: COM FOTO | I10: Capacitores | J10: 053496.png | K10: CAPACITOR-COM-FIO-250V-CBB60.jpg | L10: CAPACITOR CBB60 7UF+-5%X250V COM FIO | M10: [Referência vinda do catálogo] Referência vazia na planilha; usada a do catálogo: CBB60
B11: 053497 | C11: CAPACITOR CBB60, 8UF +-5% X 250V COM FIO FACON | D11: CBB60 | E11: FACON | F11: Capacitor de funcionamento CBB60 com cabos (fios) de ligação, 250 VAC, tolerância ±5%, 50/60 Hz. Uso em motores monofásicos. | G11: 80 | H11: COM FOTO | I11: Capacitores | J11: 053497.png | K11: CAPACITOR-COM-FIO-250V-CBB60.jpg | L11: CAPACITOR CBB60 8UF +-5%X250V COM FIO | M11: [Referência vinda do catálogo] Referência vazia na planilha; usada a do catálogo: CBB60
B12: 055201 | C12: CAPACITOR CBB60, 8UF +-5% X 250V FACON | D12: CBB60 | E12: FACON | F12: Capacitor de funcionamento (permanente) CBB60, 250 VAC, tolerância ±5%, 50/60 Hz, terminais tipo faston. Uso em motores monofásicos (ventiladores, bombas, lavadoras). | G12: 1 | H12: COM FOTO | I12: Capacitores | J12: 055201.png | K12: CAPACITOR-SIMPLES-250V-CBB60.jpg | L12: CAPACITOR SIMPLES CBB60 8UF+-5%X250V | M12: [Referência vinda do catálogo] Referência vazia na planilha; usada a do catálogo: CBB60
B13: 053140 | C13: CAPACITOR CBB60, 10UF +-5% X 250V FACON | D13: CBB60 | E13: FACON | F13: Capacitor de funcionamento (permanente) CBB60, 250 VAC, tolerância ±5%, 50/60 Hz, terminais tipo faston. Uso em motores monofásicos (ventiladores, bombas, lavadoras). | G13: 6 | H13: COM FOTO | I13: Capacitores | J13: 053140.png | K13: CAPACITOR-SIMPLES-250V-CBB60.jpg | L13: CAPACITOR SIMPLES CBB60 10UF +-5% X 250V | M13: [Referência vinda do catálogo] Referência vazia na planilha; usada a do catálogo: CBB60
B14: 053504 | C14: CAPACITOR CBB60, 15UF +-5% X 250V COM FIO FACON | D14: CBB60 | E14: FACON | F14: Capacitor de funcionamento CBB60 com cabos (fios) de ligação, 250 VAC, tolerância ±5%, 50/60 Hz. Uso em motores monofásicos. | G14: 19 | H14: COM FOTO | I14: Capacitores | J14: 053504.png | K14: CAPACITOR-COM-FIO-250V-CBB60.jpg | L14: CAPACITOR CBB60 15UF+-5%X250V COM FIO | M14: [Referência vinda do catálogo] Referência vazia na planilha; usada a do catálogo: CBB60
B15: 054104 | C15: CAPACITOR CBB60, 15UF +-5% X 250V FACON | D15: CBB60 | E15: FACON | F15: Capacitor de funcionamento (permanente) CBB60, 250 VAC, tolerância ±5%, 50/60 Hz, terminais tipo faston. Uso em motores monofásicos (ventiladores, bombas, lavadoras). | G15: 5 | H15: COM FOTO | I15: Capacitores | J15: 054104.png | K15: CAPACITOR-SIMPLES-250V-CBB60.jpg | L15: CAPACITOR SIMPLES CBB60 15UF +-5% X 250V | M15: [Referência vinda do catálogo] Referência vazia na planilha; usada a do catálogo: CBB60
B16: 053505 | C16: CAPACITOR CBB60, 17.5UF +-5% X 250V COM FIO FACON | D16: CBB60 | E16: FACON | F16: Capacitor de funcionamento CBB60 com cabos (fios) de ligação, 250 VAC, tolerância ±5%, 50/60 Hz. Uso em motores monofásicos. | G16: 49 | H16: COM FOTO | I16: Capacitores | J16: 053505.png | K16: CAPACITOR-COM-FIO-250V-CBB60.jpg | L16: CAPACITOR CBB60 17,5UF+-5%X250V COM FIO | M16: [Referência vinda do catálogo] Referência vazia na planilha; usada a do catálogo: CBB60
B17: 053506 | C17: CAPACITOR CBB60, 20UF +-5% X 250V COM FIO FACON | D17: CBB60 | E17: FACON | F17: Capacitor de funcionamento CBB60 com cabos (fios) de ligação, 250 VAC, tolerância ±5%, 50/60 Hz. Uso em motores monofásicos. | G17: 276 | H17: COM FOTO | I17: Capacitores | J17: 053506.png | K17: CAPACITOR-COM-FIO-250V-CBB60.jpg | L17: CAPACITOR CBB60 20UF+-5%X250V COM FIO | M17: [Referência vinda do catálogo] Referência vazia na planilha; usada a do catálogo: CBB60
B18: 053141 | C18: CAPACITOR CBB60, 20UF +-5% X 250V FACON | D18: CBB60 | E18: FACON | F18: Capacitor de funcionamento (permanente) CBB60, 250 VAC, tolerância ±5%, 50/60 Hz, terminais tipo faston. Uso em motores monofásicos (ventiladores, bombas, lavadoras). | G18: 5 | H18: COM FOTO | I18: Capacitores | J18: 053141.png | K18: CAPACITOR-SIMPLES-250V-CBB60.jpg | L18: CAPACITOR SIMPLES CBB60 20UF+-5%X250V | M18: [Referência vinda do catálogo] Referência vazia na planilha; usada a do catálogo: CBB60
... B69: 053139 | C69: CAPACITOR DUPLO CBB65, 55UF + 6UF X 440VAC FACON | D69: CBB65 | E69: FACON | F69: Capacitor duplo CBB65 (compressor + ventilador) em um só corpo, 3 bornes (C / HERM / FAN). Capacitâncias no formato compressor + ventilador; tensão conforme descrição. | G69: 44 | H69: COM FOTO | I69: Capacitores | J69: 053139.png | K69: CAPACITOR-DUPLO-440V-250V-CBB65.jpg | L69: CAPACITOR DUPLO CBB65 55UF +6UF X 440VAC | M69: [Referência vinda do catálogo] Referência vazia na planilha; usada a do catálogo: CBB65
B70: 054357 | C70: LUVA NITRILO VERDE 33CM 8 | D70: VE801VE08 | E70: DELTAPLUS | F70: Luva nitrílica de cano longo (33 cm) para manuseio de produtos químicos. | G70: 6 | H70: COM FOTO | I70: EPI / Segurança | J70: 054357.png | K70: LUVA-NITRILICA-33-CM-NITREX-VE801.jpg | L70: LUVA NITRÍLICA 33 CM NITREX VE801
B71: 054358 | C71: LUVA NITRILO VERDE 33CM 9 | D71: VE801VE09 | E71: DELTAPLUS | F71: Luva nitrílica de cano longo (33 cm) para manuseio de produtos químicos. | G71: 1 | H71: COM FOTO | I71: EPI / Segurança | J71: 054358.png | K71: LUVA-NITRILICA-33-CM-NITREX-VE801.jpg | L71: LUVA NITRÍLICA 33 CM NITREX VE801
B72: 054338 | C72: OCULOS SUMMER INCOLOR | D72: WPS0254 | E72: DELTAPLUS | F72: Óculos de segurança com proteção UVA/UVB, lente incolor. | G72: 2 | H72: COM FOTO | I72: EPI / Segurança | J72: 054338.png | K72: 054338_OCULOS-SUMMER-INCOLOR.jpg | L72: ÓCULOS PROTEÇÃO UVA UVB SUMMER
B73: 054824 | C73: SAPATO ELESTICO BRANCO SEM BICO MONO TPB100 38 CARTON | D73: 4068 | E73: CARTON | F73: Sapato ocupacional branco com elástico lateral, sem biqueira. Numeração ao final da descrição. | G73: 3 | H73: COM FOTO | I73: EPI / Segurança | J73: 054824.png | K73: SAPATO-ELASTICO-S-BICO-TPB100.jpg | L73: SAPATO ELÁSTICO BRANCO SEM BICO MONO TPB100 38 CARTON
B74: 054825 | C74: SAPATO ELESTICO BRANCO SEM BICO MONO TPB100 39 CARTON | D74: 4069 | E74: CARTON | F74: Sapato ocupacional branco com elástico lateral, sem biqueira. Numeração ao final da descrição. | G74: 2 | H74: COM FOTO | I74: EPI / Segurança | J74: 054825.png | K74: SAPATO-ELASTICO-S-BICO-TPB100.jpg | L74: SAPATO ELÁSTICO BRANCO SEM BICO MONO TPB100 39 CARTON
B75: 054826 | C75: SAPATO ELESTICO BRANCO SEM BICO MONO TPB100 40 CARTON | D75: 4070 | E75: CARTON | F75: Sapato ocupacional branco com elástico lateral, sem biqueira. Numeração ao final da descrição. | G75: 4 | H75: COM FOTO | I75: EPI / Segurança | J75: 054826.png | K75: SAPATO-ELASTICO-S-BICO-TPB100.jpg | L75: SAPATO ELÁSTICO BRANCO SEM BICO MONO TPB100 40 CARTON
B76: 054827 | C76: SAPATO ELESTICO BRANCO SEM BICO MONO TPB100 41 CARTON | D76: 4071 | E76: CARTON | F76: Sapato ocupacional branco com elástico lateral, sem biqueira. Numeração ao final da descrição. | G76: 3 | H76: COM FOTO | I76: EPI / Segurança | J76: 054827.png | K76: SAPATO-ELASTICO-S-BICO-TPB100.jpg | L76: SAPATO ELÁSTICO BRANCO SEM BICO MONO TPB100 41 CARTON
B77: 054828 | C77: SAPATO ELESTICO BRANCO SEM BICO MONO TPB100 42 CARTON | D77: 4072 | E77: CARTON | F77: Sapato ocupacional branco com elástico lateral, sem biqueira. Numeração ao final da descrição. | G77: 3 | H77: COM FOTO | I77: EPI / Segurança | J77: 054828.png | K77: SAPATO-ELASTICO-S-BICO-TPB100.jpg | L77: SAPATO ELÁSTICO BRANCO SEM BICO MONO TPB100 42 CARTON
B78: 054829 | C78: SAPATO ELESTICO BRANCO SEM BICO MONO TPB100 43 CARTON | D78: 4073 | E78: CARTON | F78: Sapato ocupacional branco com elástico lateral, sem biqueira. Numeração ao final da descrição. | G78: 1 | H78: COM FOTO | I78: EPI / Segurança | J78: 054829.png | K78: SAPATO-ELASTICO-S-BICO-TPB100.jpg | L78: SAPATO ELÁSTICO BRANCO SEM BICO MONO TPB100 43 CARTON
B79: 054830 | C79: SAPATO ELESTICO BRANCO SEM BICO MONO TPB100 44 CARTON | D79: 4074 | E79: CARTON | F79: Sapato ocupacional branco com elástico lateral, sem biqueira. Numeração ao final da descrição. | G79: 3 | H79: COM FOTO | I79: EPI / Segurança | J79: 054830.png | K79: SAPATO-ELASTICO-S-BICO-TPB100.jpg | L79: SAPATO ELÁSTICO BRANCO SEM BICO MONO TPB100 44 CARTON
B80: 054838 | C80: SAPATO POLIMERICO BRANCO SEM BICO BIDENCID COB101 36 CARTON | D80: 7947 | E80: CARTON | F80: Sapato polimérico branco, sem biqueira, fácil de lavar. Numeração ao final da descrição. | G80: 6 | H80: COM FOTO | I80: EPI / Segurança | J80: 054838.png | K80: SAPATO-BRANCO-SEM-BICO-COB-101.jpg | L80: SAPATO POLIMÉRICO BRANCO SEM BICO BIDENCID COB101 36 CARTON
B81: 054839 | C81: SAPATO POLIMERICO BRANCO SEM BICO BIDENCID COB101 37 CARTON | D81: 7948 | E81: CARTON | F81: Sapato polimérico branco, sem biqueira, fácil de lavar. Numeração ao final da descrição. | G81: 10 | H81: COM FOTO | I81: EPI / Segurança | J81: 054839.png | K81: SAPATO-BRANCO-SEM-BICO-COB-101.jpg | L81: SAPATO POLIMÉRICO BRANCO SEM BICO BIDENCID COB101 37 CARTON
... B88: 055104 | C88: CONJ BOTAO DUPLO PULSADOR FACEADO VISOR VERMELHO + BLOCOS | D88: 17457 | E88: MARGIRIUS | F88: Botão duplo pulsador com visor vermelho e blocos de contato. | G88: 15 | H88: COM FOTO | I88: Elétrica / Comandos | J88: 055104.png | K88: 055104_CONJ-BOTAO-DUPLO-PULSADOR-FACEADO-VISOR-VERMELHO-B.jpg | L88: CONJUNTO BOTÃO DUPLO PULSADOR FACEADO VISOR VERMELHO + BLOCOS
B89: 054084 | C89: CONTATOR ELETROMAGNETICO 3 POLOS 30A 220V P A/C FACON | E89: FACON | F89: Contator magnético com bobina 220 V para acionamento de motores e compressores; nº de polos (MONO/BIF/TRIF) e corrente nominal na descrição. | G89: 2 | H89: COM FOTO | I89: Elétrica / Comandos | J89: 054084.png | K89: CONTATOR-MAGNETICO.jpg | L89: CONTATOR MAGNÉTICO 220V TRIF 30A FACON
B90: 052306 | C90: CONTATOR ELETROMAGNETICO 220V 18A CHNT | E90: CHINT | F90: Contator magnético com bobina 220 V para acionamento de motores e compressores; nº de polos (MONO/BIF/TRIF) e corrente nominal na descrição. | G90: 1 | H90: COM FOTO | I90: Elétrica / Comandos | J90: 052306.png | K90: CONTATOR-MAGNETICO.jpg | L90: CONTATOR MAGNÉTICO 220V 18A CHINT | M90: [Marca vinda do catálogo] Fabricante vazio na planilha; usada a marca do catálogo: CHINT
B91: 052336 | C91: CONTATOR ELETROMAGNETICO 220V TRIF 9A DECORLUX | D91: C0-0910M7 | E91: DECORLUX | F91: Contator magnético com bobina 220 V para acionamento de motores e compressores; nº de polos (MONO/BIF/TRIF) e corrente nominal na descrição. | G91: 77 | H91: COM FOTO | I91: Elétrica / Comandos | J91: 052336.png | K91: CONTATOR-MAGNETICO.jpg | L91: CONTATOR MAGNÉTICO 220V TRIF 9A DECORLUX
B92: 051846 | C92: CONTATOR ELETROMAGNETICO 220V TRIF 12A DECORLUX | D92: C0-1210M7 | E92: DECORLUX | F92: Contator magnético com bobina 220 V para acionamento de motores e compressores; nº de polos (MONO/BIF/TRIF) e corrente nominal na descrição. | G92: 65 | H92: COM FOTO | I92: Elétrica / Comandos | J92: 051846.png | K92: CONTATOR-MAGNETICO.jpg | L92: CONTATOR MAGNÉTICO 220V TRIF 12A DECORLUX
B93: 001049 | C93: CONTATOR ELETROMAGNETICO 220V TRIF 18A DECORLUX | D93: CO-1810M7 | E93: DECORLUX | F93: Contator magnético com bobina 220 V para acionamento de motores e compressores; nº de polos (MONO/BIF/TRIF) e corrente nominal na descrição. | G93: 120 | H93: COM FOTO | I93: Elétrica / Comandos | J93: 001049.png | K93: CONTATOR-MAGNETICO.jpg | L93: CONTATOR MAGNÉTICO 220V TRIF 18A DECORLUX
B94: 053854 | C94: CONTATOR ELETROMAGNETICO 220V TRIF 80A DECORLUX | D94: CO-8011M7 | E94: DECORLUX | F94: Contator magnético com bobina 220 V para acionamento de motores e compressores; nº de polos (MONO/BIF/TRIF) e corrente nominal na descrição. | G94: 1 | H94: COM FOTO | I94: Elétrica / Comandos | J94: 053854.png | K94: CONTATOR-MAGNETICO.jpg | L94: CONTATOR MAGNÉTICO 220V TRIF 80A DECORLUX
B95: 053708 | C95: CONTATOR ELETROMAGNETICO TRIF 40A 220V LC1-D4011M7 FACON | D95: LC1-D4011M7 | E95: FACON | F95: Contator magnético com bobina 220 V para acionamento de motores e compressores; nº de polos (MONO/BIF/TRIF) e corrente nominal na descrição. | G95: 1 | H95: COM FOTO | I95: Elétrica / Comandos | J95: 053708.png | K95: CONTATOR-MAGNETICO.jpg | L95: CONTATOR MAGNÉTICO 220V TRIF 40A FACON
B96: 055097 | C96: DPS DISPOSITIVO DE PROTECAO CONTRA SURTO 12KA 127V CLASSE II | D96: 18673 | E96: MARGIRIUS | F96: DPS (dispositivo de proteção contra surtos) 12 kA, 127 V, classe II, trilho DIN. | G96: 5 | H96: COM FOTO | I96: Elétrica / Comandos | J96: 055097.png | K96: DPS-DISPOSITIVO-DE-PROTECAO-CONTRA-SURTO-45KA-127V.jpg | L96: DPS DISPOSITIVO DE PROTEÇÃO CONTRA SURTO 12K 127V CLASSE II
...

Sheet SEM FOTO (BUSCAR)
A1: CÓDIGO | B1: DESCRIÇÃO | C1: REFERÊNCIA | D1: FABRICANTE | E1: SALDO | F1: CATEGORIA | G1: STATUS | H1: TERMO DE BUSCA SUGERIDO
A2: 003468 | B2: TERMINAL PINO AZUL PRE ISOLADO 1,5-2,5MM 27A | C2: TP-2022 | D2: DECORLUX | E2: 12126 | F2: Elétrica / Comandos | G2: SEM FOTO | H2: DECORLUX TP-2022 TERMINAL PINO AZUL PRE ISOLADO 1,5-2,5MM 27A
A3: 054371 | B3: TERMINAL GARFO M4 VERMELHO PRE ISOLADO 0,5-1,5MM 9A | C3: TG-4097 | D3: DECORLUX | E3: 9622 | F3: Elétrica / Comandos | G3: SEM FOTO | H3: DECORLUX TG-4097 TERMINAL GARFO M4 VERMELHO PRE ISOLADO 0,5-1,5MM 9A
A4: 003436 | B4: BUCHA S6 VAZADA P TIJOLO OCO UNIDADE USAF | C4: 000085 | D4: USAF | E4: 8565 | F4: Fixação e Acessórios | G4: SEM FOTO | H4: USAF 000085 BUCHA S6 VAZADA P TIJOLO OCO UNIDADE USAF
A5: 000032 | B5: TERMINAL ANEL M4 AZUL PRE ISOLADO 1,5-2,5MM 27A | C5: TA-4272 | D5: DECORLUX | E5: 8109 | F5: Elétrica / Comandos | G5: SEM FOTO | H5: DECORLUX TA-4272 TERMINAL ANEL M4 AZUL PRE ISOLADO 1,5-2,5MM 27A
A6: 054530 | B6: BUCHA S12 VAZADA P TIJOLO OCO UNIDADE USAF | C6: S12 | D6: USAF | E6: 7972 | F6: Fixação e Acessórios | G6: SEM FOTO | H6: USAF S12 BUCHA S12 VAZADA P TIJOLO OCO UNIDADE USAF
A7: 060199 | B7: TERMINAL BANDEIRA COBRE ESTANHADO ISOLADO NYLON, 1,5-2,5 | C7: TB1525 | D7: DECORLUX | E7: 7945 | F7: Elétrica / Comandos | G7: SEM FOTO | H7: DECORLUX TB1525 TERMINAL BANDEIRA COBRE ESTANHADO ISOLADO NYLON, 1,5-2,5
A8: 003469 | B8: TERMINAL FEMEA AMARELO PRE ISOLADO 4,0-6,0MM 24A | C8: TF6241 | D8: DECORLUX | E8: 7188 | F8: Elétrica / Comandos | G8: SEM FOTO | H8: DECORLUX TF6241 TERMINAL FEMEA AMARELO PRE ISOLADO 4,0-6,0MM 24A
A9: 003437 | B9: BUCHA S10 VAZADA P TIJOLO OCO UNIDADE USAF | C9: U2524F | D9: USAF | E9: 6501 | F9: Fixação e Acessórios | G9: SEM FOTO | H9: USAF U2524F BUCHA S10 VAZADA P TIJOLO OCO UNIDADE USAF
A10: 003448 | B10: PF A/A 3.9X32 CH ZIN PHS JOMARCA | C10: 01686 | D10: JOMARCA | E10: 6165 | F10: Fixação e Acessórios | G10: SEM FOTO | H10: JOMARCA 01686 PF A/A 3.9X32 CH ZIN PHS JOMARCA
A11: 060200 | B11: TERMINAL BANDEIRA COBRE ESTANHADO ISOLADO NYLON, 4-6 | C11: TB0406 | D11: DECORLUX | E11: 6008 | F11: Elétrica / Comandos | G11: SEM FOTO | H11: DECORLUX TB0406 TERMINAL BANDEIRA COBRE ESTANHADO ISOLADO NYLON, 4-6
A12: 056732 | B12: TERMINAL FEMEA AZUL PRE ISOLADO 1,5-2,5MM CNC FDD2-250 | C12: FDD2-250-C | D12: CNC | E12: 5098 | F12: Elétrica / Comandos | G12: SEM FOTO | H12: CNC FDD2-250-C TERMINAL FEMEA AZUL PRE ISOLADO 1,5-2,5MM CNC FDD2-250
A13: 057316 | B13: TERMINAL ENCAIXE MACHO AZUL 1,5-2,5MM - CNC REF: MDD2-250 | C13: MDD2-250 | D13: CNC | E13: 4799 | F13: Elétrica / Comandos | G13: SEM FOTO | H13: CNC MDD2-250 TERMINAL ENCAIXE MACHO AZUL 1,5-2,5MM - CNC REF: MDD2-250
... A23: 000280 | B23: TERMINAL FEMEA AZUL PRE ISOLADO 1,5-2,5MM 15A | C23: TF-2152 | D23: DECORLUX | E23: 2770 | F23: Elétrica / Comandos | G23: SEM FOTO | H23: DECORLUX TF-2152 TERMINAL FEMEA AZUL PRE ISOLADO 1,5-2,5MM 15A
A24: 001105 | B24: CURVA CO 90 CURTA 1/2 | D24: FACON | E24: 2650 | F24: Instalação de Ar-Condicionado | G24: SEM FOTO | H24: FACON CURVA CO 90 CURTA 1/2
A25: 056317 | B25: PF JMC DRILL SX C ARR+N PTA BROCA 14X3/4 ZIN NT-217 JOMAR | C25: 31261 | D25: JOMARCA | E25: 2528 | F25: Ferramentas / Instrumentos | G25: SEM FOTO | H25: JOMARCA 31261 PF JMC DRILL SX C ARR+N PTA BROCA 14X3/4 ZIN NT-217 JOMAR
A26: 056203 | B26: LUVA 20X10 ENERBRAS 360-E4 | C26: 360-E4 | D26: ENERBRAS | E26: 2522 | F26: EPI / Segurança | G26: SEM FOTO | H26: ENERBRAS 360-E4 LUVA 20X10 ENERBRAS 360-E4
A27: 056318 | B27: PF JMC DRILL SX C ARR+N PTA BROCA 12X1 ZIN NT-217 JOMAR | C27: 31243 | D27: JOMARCA | E27: 2499 | F27: Ferramentas / Instrumentos | G27: SEM FOTO | H27: JOMARCA 31243 PF JMC DRILL SX C ARR+N PTA BROCA 12X1 ZIN NT-217 JOMAR
A28: 056202 | B28: COTOVELO 90 GRAUS 20X10 ENERBRAS 360-E7 | C28: 360-E7 | D28: ENERBRAS | E28: 2495 | F28: Hidráulica | G28: SEM FOTO | H28: ENERBRAS 360-E7 COTOVELO 90 GRAUS 20X10 ENERBRAS 360-E7
A29: 060602 | B29: PF A/A 4.8X45 CH PH ZB CISTER CX 200 | C29: 35167701 | D29: CISER | E29: 2490 | F29: Fixação e Acessórios | G29: SEM FOTO | H29: CISER 35167701 PF A/A 4.8X45 CH PH ZB CISTER CX 200
A30: 057661 | B30: MODULO LED 5054-3 LED-7512 0.72W IP65 | C30: TB-1173 | E30: 2452 | F30: Iluminação | G30: SEM FOTO | H30: TB-1173 MODULO LED 5054-3 LED-7512 0.72W IP65
A31: 059577 | B31: VALVULA SCHIRADER 1/4 X50MM VIX | C31: 1016635 | D31: VIX | E31: 2304 | F31: Refrigeração / Componentes | G31: SEM FOTO | H31: VIX 1016635 VALVULA SCHIRADER 1/4 X50MM VIX
A32: 058759 | B32: VALVULA SCHIRADER 1/4 P 0,5MM HULTER | C32: 100265347 | D32: HULTER | E32: 2286 | F32: Refrigeração / Componentes | G32: SEM FOTO | H32: HULTER 100265347 VALVULA SCHIRADER 1/4 P 0,5MM HULTER
A33: 052891 | B33: CURVA CO 90 CURTA 1/4 | D33: FACON | E33: 2226 | F33: Instalação de Ar-Condicionado | G33: SEM FOTO | H33: FACON CURVA CO 90 CURTA 1/4
A34: 003438 | B34: BUCHA S8 VAZADA P TIJOLO OCO UNIDADE USAF | C34: 000086 | D34: USAF | E34: 2169 | F34: Fixação e Acessórios | G34: SEM FOTO | H34: USAF 000086 BUCHA S8 VAZADA P TIJOLO OCO UNIDADE USAF
A35: 056319 | B35: PF JMC DRILL SX C ARR+N PTA BROCA 14X1 ZIN NT-217 JOMAR | C35: 31262 | D35: JOMARCA | E35: 2058 | F35: Ferramentas / Instrumentos | G35: SEM FOTO | H35: JOMARCA 31262 PF JMC DRILL SX C ARR+N PTA BROCA 14X1 ZIN NT-217 JOMAR
A36: 056357 | B36: CONECTOR DE DERIVACAO 1.5-2.5MM AZUL | C36: CD-1525 | D36: DECORLUX | E36: 1986 | F36: Elétrica / Comandos | G36: SEM FOTO | H36: DECORLUX CD-1525 CONECTOR DE DERIVACAO 1.5-2.5MM AZUL
A37: 060615 | B37: TERMINAL GARFO PRE ISOL FORQ 1,3/2,6 M3 AZUL CRIMPER FR2477 | C37: 215367 | D37: CRIMPER | E37: 1869 | F37: Elétrica / Comandos | G37: SEM FOTO | H37: CRIMPER 215367 TERMINAL GARFO PRE ISOL FORQ 1,3/2,6 M3 AZUL CRIMPER FR2477
A38: 056314 | B38: PF A/A JMC DRILL FL PHS C SEEILHA 4.2X13MM ZIN NT-422 JOMAR | C38: 09101 | D38: JOMARCA | E38: 1774 | F38: Fixação e Acessórios | G38: SEM FOTO | H38: JOMARCA 09101 PF A/A JMC DRILL FL PHS C SEEILHA 4.2X13MM ZIN NT-422 JOMAR
A39: 000990 | B39: ARRUELA LISA ZIN 5/16 UNIDADE | D39: JOMARCA | E39: 1771 | F39: Fixação e Acessórios | G39: SEM FOTO | H39: JOMARCA ARRUELA LISA ZIN 5/16 UNIDADE
A40: 057135 | B40: TERMINAL GARFO PRE ISOLADO 4MM-6MM | C40: TP-G40 | D40: TRIAL | E40: 1661 | F40: Elétrica / Comandos | G40: SEM FOTO | H40: TRIAL TP-G40 TERMINAL GARFO PRE ISOLADO 4MM-6MM
A41: 060482 | B41: FITA PVC 10M BRANCA SIMPLES REFRIPLAY | C41: EC10BS | D41: REFRIPLAY IND | E41: 1655 | F41: Instalação de Ar-Condicionado | G41: SEM FOTO | H41: REFRIPLAY IND EC10BS FITA PVC 10M BRANCA SIMPLES REFRIPLAY
A42: 053645 | B42: TERMINAL FEMEA VERMELHO PRE ISOLADO 0,5-1,5MM 10A | C42: TF-1107 | D42: DECORLUX | E42: 1653 | F42: Elétrica / Comandos | G42: SEM FOTO | H42: DECORLUX TF-1107 TERMINAL FEMEA VERMELHO PRE ISOLADO 0,5-1,5MM 10A
A43: 055193 | B43: NUCLEO DA VALVULA SCHIRIDER VALVULA FACON | D43: FACON | E43: 1610 | F43: Refrigeração / Componentes | G43: SEM FOTO | H43: FACON NUCLEO DA VALVULA SCHIRIDER VALVULA FACON
A44: 057318 | B44: TERMINAL GARFO PRE ISOLADO 1,5MM-2,5MM - AZUL REF: SVS 2-4C | C44: SVS 2-4S | D44: CNC | E44: 1600 | F44: Elétrica / Comandos | G44: SEM FOTO | H44: CNC SVS 2-4S TERMINAL GARFO PRE ISOLADO 1,5MM-2,5MM - AZUL REF: SVS 2-4C
A45: 060664 | B45: CABO FLEX 1.5MM BOBINA COM 1600 METROS VERDE 450/750V | C45: FLEXPA2.20.1340.0 | D45: FLEXCABLES | E45: 1600 | F45: Elétrica / Comandos | G45: SEM FOTO | H45: FLEXCABLES FLEXPA2.20.1340.0 CABO FLEX 1.5MM BOBINA COM 1600 METROS VERDE 450/750V
A46: 059316 | B46: TERMINAL OLHAL PRE ISOLADO VERMELHO 0,5-1,5MM CNC REF: RV1.2 | C46: RV1.25-4S | D46: CNC | E46: 1528 | F46: Elétrica / Comandos | G46: SEM FOTO | H46: CNC RV1.25-4S TERMINAL OLHAL PRE ISOLADO VERMELHO 0,5-1,5MM CNC REF: RV1.2
A47: 003457 | B47: PORCA ZIN BR UNC 5/16 UND | C47: 31224 | D47: JOMARCA | E47: 1426 | F47: Fixação e Acessórios | G47: SEM FOTO | H47: JOMARCA 31224 PORCA ZIN BR UNC 5/16 UND
A48: 059313 | B48: TERMINAL FEMEA VERMELHO 0,5-1,5MM - CNC REF: FDD1.5-187 | C48: FDD1.5-187 | D48: CNC | E48: 1327 | F48: Elétrica / Comandos | G48: SEM FOTO | H48: CNC FDD1.5-187 TERMINAL FEMEA VERMELHO 0,5-1,5MM - CNC REF: FDD1.5-187
A49: 003433 | B49: ARRUELA LISA ZIN 1/4 UNIDADE | D49: JOMARCA | E49: 1195 | F49: Fixação e Acessórios | G49: SEM FOTO | H49: JOMARCA ARRUELA LISA ZIN 1/4 UNIDADE
...

Sheet DIVERGÊNCIAS
A1: CÓDIGO | B1: DESCRIÇÃO (PLANILHA) | C1: TIPO | D1: DETALHE / O QUE CONFERIR | E1: STATUS DA FOTO
A2: 052222 | B2: RELE TERMICO E SOBRECARGA NXR-38 23A-32A CHINT | C2: Marca diferente | D2: Planilha: CHINT | Catálogo: DECORLUX — a foto do catálogo é de outra marca e NÃO foi usada. | E2: FOTO NÃO CONFERE
A3: 052222 | B3: RELE TERMICO E SOBRECARGA NXR-38 23A-32A CHINT | C3: Descrição diferente para o mesmo código | D3: Catálogo: 'RELÉ TÉRMICO 36A AJUSTE 23-32A DECORLUX' | Planilha: 'RELE TERMICO E SOBRECARGA NXR-38 23A-32A CHINT' (números só no catálogo: 36) | E3: FOTO NÃO CONFERE
A4: 052764 | B4: CAPACITOR CBB65, 17.5UF +-5% X 440VAC 50-60HZ FACON | C4: Descrição diferente para o mesmo código | D4: Catálogo: 'CAPACITOR SIMPLES CBB65 17UF +-5%X440V' | Planilha: 'CAPACITOR CBB65, 17.5UF +-5% X 440VAC 50-60HZ FACON' (números só no catálogo: 17) | E4: COM FOTO
A5: 052926 | B5: MICRO MOTOR 1/25 12W 110V 1550/1750 RPM HELICE PLASTIC FACON | C5: Descrição diferente para o mesmo código | D5: Catálogo: 'MICRO MOTOR 1/25 12/40W 110V 1550 RPM HÉLICE DE ALUMÍNIO FACON' | Planilha: 'MICRO MOTOR 1/25 12W 110V 1550/1750 RPM HELICE PLASTIC FACON' (números só no catálogo: 12/40, 1550) | E5: COM FOTO
A6: 053680 | B6: TERMOSTATO FREEZ HORIZ DUPLA ACAO ELECTR/METALFRI RFR-4009-2 | C6: Descrição diferente para o mesmo código | D6: Catálogo: 'TERMOSTATO RC-4209-2' | Planilha: 'TERMOSTATO FREEZ HORIZ DUPLA ACAO ELECTR/METALFRI RFR-4009-2' (números só no catálogo: 4209) | E6: COM FOTO
A7: 053682 | B7: TERMOSTATO BEBEDOURO/REFRESQUEIRA STANDARD RC-42600-2 | C7: Descrição diferente para o mesmo código | D7: Catálogo: 'TERMOSTATO RC- 53600-2' | Planilha: 'TERMOSTATO BEBEDOURO/REFRESQUEIRA STANDARD RC-42600-2' (números só no catálogo: 53600) | E7: COM FOTO
A8: 053943 | B8: MANGUEIRA GROSSA 9,52 X 1,6MM PACOTE 2 MT | C8: Descrição diferente para o mesmo código | D8: Catálogo: 'MANGUEIRA ESPECIAL 8 X 1,66MM PACOTE 2M' | Planilha: 'MANGUEIRA GROSSA 9,52 X 1,6MM PACOTE 2 MT' (números só no catálogo: 1.66, 8) | E8: COM FOTO
A9: 054147 | B9: RELE CONTATOR 4 PINOS 18A/277VAC FACON | C9: Descrição diferente para o mesmo código | D9: Catálogo: 'RELÉ CONTATOR 4 PINOS 30A/277VAC' | Planilha: 'RELE CONTATOR 4 PINOS 18A/277VAC FACON' (números só no catálogo: 30) | E9: COM FOTO
A10: 055090 | B10: TOMADA QUINTAPLA 2P+T CINZA 20A PARA EXTENSAO TMU5-320 17775 | C10: Descrição diferente para o mesmo código | D10: Catálogo: 'TOMADA QUÍNTUPLA 2P + T CINZA 20A PARA EXTENSÃO TMU3-320' | Planilha: 'TOMADA QUINTAPLA 2P+T CINZA 20A PARA EXTENSAO TMU5-320 17775' (números só no catálogo: 3) | E10: COM FOTO
A11: 052778 | B11: CAPACITOR DUPLO CBB65, 25UF + 10UF X 440VAC FACON | C11: Código repetido no catálogo | D11: No catálogo este código também aparece em: CAPACITOR DUPLO CBB65 35UF+6UF X 440VAC. Foto escolhida pela descrição. | E11: COM FOTO
A12: 052787 | B12: CAPACITOR DUPLO CBB65, 25UF + 1.5UF X 440VAC FACON | C12: Código repetido no catálogo | D12: No catálogo este código também aparece em: CAPACITOR DUPLO CBB65 25UF+ 10UF X 440VAC. Foto escolhida pela descrição. | E12: COM FOTO
... A114: 052793 | B114: CAPACITOR DUPLO CBB65, 55UF + 2.5UF X 440VAC FACON | C114: Marca vinda do catálogo (informativo) | D114: Fabricante vazio na planilha; usada a marca do catálogo: FACON | E114: FOTO DE PRODUTO EQUIVALENTE

Sheet CATÁLOGO FORA DA LISTA
A1: IMAGEM | B1: CÓD. NO CATÁLOGO | C1: DESCRIÇÃO NO CATÁLOGO | D1: CATEGORIA | E1: MOTIVO | F1: POSSÍVEL CÓDIGO NA LISTA (pela descrição) | G1: PÁG. CATÁLOGO
B2: 54850 | C2: PROGRAMADOR HORA DE ENERGIA BWT-40 REF- BWT-40HR-P COEL | D2: Automação / Temporizadores | E2: Código não está na lista (sem saldo na loja ou código diferente) | G2: 6
B3: 54857 | C3: RELÉ DE TEMPO 6H 30 MIN (EQUIVALENTE ICEMATIC 94A 240VAC REF-11107002 - COEL | D3: Automação / Temporizadores | E3: Código não está na lista (sem saldo na loja ou código diferente) | G3: 6
B4: 54856 | C4: RELÉ DE TEMPO AEGMU MULT ESCALA COEL REF-AEGMU | D4: Automação / Temporizadores | E4: Código não está na lista (sem saldo na loja ou código diferente) | G4: 6
B5: 54979 | C5: RELÉ DE TEMPO AG-ALIM 94A 242VAC 15 MINUTOS REF-AEG-UEM-P | D5: Automação / Temporizadores | E5: Código não está na lista (sem saldo na loja ou código diferente) | G5: 6
B6: 54977 | C6: RELÉ DE TEMPO AG-ALIM 94A 242VAC 15 SEGUNDOS REF-AEG-UES-P | D6: Automação / Temporizadores | E6: Código não está na lista (sem saldo na loja ou código diferente) | G6: 6
B7: 55520 | C7: RELÉ DE TEMPO AG-ALIM 94A 242VAC 60 SEGUNDOS REF-AEG-UGS-P | D7: Automação / Temporizadores | E7: Código não está na lista (sem saldo na loja ou código diferente) | G7: 6
B8: S/ CÓDIGO | C8: RELÉ DE TEMPO RTDF 12H 60 MIN COEL | D8: Automação / Temporizadores | E8: Produto sem código no catálogo e não identificado na lista
B9: 54856 | C9: RELÉ DE TEMPO T42 ALIM 100 A 240V REF- T42HLRR-KP COEL | D9: Automação / Temporizadores | E9: Código não está na lista (sem saldo na loja ou código diferente) | G9: 6
B10: 54856 | C10: RELÉ ELETRÔNICO DIGITAL FALTA DE FASE BVF-1P REF- BVF1-P | D10: Automação / Temporizadores | E10: Código não está na lista (sem saldo na loja ou código diferente) | G10: 6
B11: 55021 | C11: RELÉ ELETRÔNICO DIGITAL FALTA DE FASE BVF-1P REF- BVS1-P | D11: Automação / Temporizadores | E11: Código não está na lista (sem saldo na loja ou código diferente) | G11: 6
B12: 53503 | C12: CAPACITOR CBB60 10UF +-5% X 250V COM FIO | D12: Capacitores | E12: Código não está na lista (sem saldo na loja ou código diferente) | F12: 055599 — CAPACITOR CBB60, 10UF +-5% X 250V COM FIO WEG (marca WEG ≠ FACON do catálogo: produto similar, não o mesmo) | G12: 3
B13: 53507 | C13: CAPACITOR CBB60 25UF+-5%X250V COM FIO | D13: Capacitores | E13: Código não está na lista (sem saldo na loja ou código diferente) | G13: 3
B14: 53508 | C14: CAPACITOR CBB60 30UF +-5%X250V COM FIO | D14: Capacitores | E14: Código não está na lista (sem saldo na loja ou código diferente) | F14: 055604 — CAPACITOR CBB60, 30UF +-5% X 250V COM FIO WEG (marca WEG ≠ FACON do catálogo: produto similar, não o mesmo) | G14: 3
B15: 54117 | C15: CAPACITOR DUPLO CBB65 25UF+ 2.5UF X 440VAC | D15: Capacitores | E15: Código não está na lista (sem saldo na loja ou código diferente) | G15: 3
B16: 52787 | C16: CAPACITOR DUPLO CBB65 25UF+ 10UF X 440VAC | D16: Capacitores | E16: Código existe na lista, mas para outro produto (código repetido no catálogo) | F16: 052778 — CAPACITOR DUPLO CBB65, 25UF + 10UF X 440VAC FACON | G16: 3
B17: 52796 | C17: CAPACITOR DUPLO CBB65 30UF +3UF X 440VAC | D17: Capacitores | E17: Código existe na lista, mas para outro produto (código repetido no catálogo) | G17: 3
B18: 52782 | C18: CAPACITOR DUPLO CBB65 30UF+6UF X 440VAC | D18: Capacitores | E18: Código não está na lista (sem saldo na loja ou código diferente) | G18: 3
B19: 52790 | C19: CAPACITOR DUPLO CBB65 30UF+ 2.5UF X 440VAC | D19: Capacitores | E19: Código não está na lista (sem saldo na loja ou código diferente) | F19: 005035 — CAPACITOR DUPLO CBB65, 30UF + 2.5UF X 440VAC EOS (marca EOS ≠ FACON do catálogo: produto similar, não o mesmo) | G19: 3
B20: 53131 | C20: CAPACITOR DUPLO CBB65 35UF+2.5UF X 440VAC | D20: Capacitores | E20: Código não está na lista (sem saldo na loja ou código diferente) | G20: 3
B21: 52779 | C21: CAPACITOR DUPLO CBB65 35UF+5UF X 440VAC | D21: Capacitores | E21: Código não está na lista (sem saldo na loja ou código diferente) | G21: 3
B22: 52778 | C22: CAPACITOR DUPLO CBB65 35UF+6UF X 440VAC | D22: Capacitores | E22: Código existe na lista, mas para outro produto (código repetido no catálogo) | G22: 3
B23: 53846 | C23: CAPACITOR DUPLO CBB65 35UF+6UF X 440VAC | D23: Capacitores | E23: Código não está na lista (sem saldo na loja ou código diferente) | G23: 3
B24: 52791 | C24: CAPACITOR DUPLO CBB65 40UF+2.5 X 440VAC | D24: Capacitores | E24: Código não está na lista (sem saldo na loja ou código diferente) | G24: 3
B25: 52783 | C25: CAPACITOR DUPLO CBB65 40UF+6UF X 440VAC | D25: Capacitores | E25: Código não está na lista (sem saldo na loja ou código diferente) | G25: 3
B26: 53135 | C26: CAPACITOR DUPLO CBB65 45UF +2.5UF X 440VAC | D26: Capacitores | E26: Código não está na lista (sem saldo na loja ou código diferente) | G26: 3
B27: 53136 | C27: CAPACITOR DUPLO CBB65 45UF +4UF X 440VAC | D27: Capacitores | E27: Código não está na lista (sem saldo na loja ou código diferente) | G27: 3
B28: 53137 | C28: CAPACITOR DUPLO CBB65 45UF+5UF X 440VAC | D28: Capacitores | E28: Código não está na lista (sem saldo na loja ou código diferente) | F28: 004522 — CAPACITOR DUPLO CBB65, 45UF + 5UF X 440VAC EOS (marca EOS ≠ FACON do catálogo: produto similar, não o mesmo) | G28: 3
B29: 53138 | C29: CAPACITOR DUPLO CBB65 45UF+12UF X 440VAC | D29: Capacitores | E29: Código não está na lista (sem saldo na loja ou código diferente) | G29: 3
B30: 52792 | C30: CAPACITOR DUPLO CBB65 50UF +5UF X 440VAC | D30: Capacitores | E30: Código não está na lista (sem saldo na loja ou código diferente) | G30: 3
B31: 52785 | C31: CAPACITOR DUPLO CBB65 50UF+6UF X 440VAC | D31: Capacitores | E31: Código não está na lista (sem saldo na loja ou código diferente) | G31: 3
B32: 53481 | C32: CAPACITOR DUPLO CBB65 60UF+ 12UF X 250VAC | D32: Capacitores | E32: Código não está na lista (sem saldo na loja ou código diferente) | G32: 3
B33: 53122 | C33: CAPACITOR SIMPLES CBB60 10UF+-5%X250V | D33: Capacitores | E33: Código não está na lista (sem saldo na loja ou código diferente) | G33: 3
B34: 55202 | C34: CAPACITOR SIMPLES CBB60 12UF +-5% X 250V | D34: Capacitores | E34: Código não está na lista (sem saldo na loja ou código diferente) | G34: 3
B35: 53142 | C35: CAPACITOR SIMPLES CBB60 25UF+-5%X250V | D35: Capacitores | E35: Código não está na lista (sem saldo na loja ou código diferente) | G35: 3
B36: 53143 | C36: CAPACITOR SIMPLES CBB60 30UF+-5%X250V | D36: Capacitores | E36: Código não está na lista (sem saldo na loja ou código diferente) | G36: 3
B37: 53350 | C37: CAPACITOR SIMPLES CBB60 55UF+-5%X250V | D37: Capacitores | E37: Código não está na lista (sem saldo na loja ou código diferente) | G37: 3
B38: 53122 | C38: CAPACITOR SIMPLES CBB65 10UF +-5%X440V | D38: Capacitores | E38: Código não está na lista (sem saldo na loja ou código diferente) | G38: 3
B39: 52765 | C39: CAPACITOR SIMPLES CBB65 20UF +-5%X440V | D39: Capacitores | E39: Código não está na lista (sem saldo na loja ou código diferente) | G39: 3
B40: 52768 | C40: CAPACITOR SIMPLES CBB65 35UF +-5%X440V | D40: Capacitores | E40: Código não está na lista (sem saldo na loja ou código diferente) | G40: 3
...

Sheet IMAGENS ENVIADAS
A1: IMAGEM | B1: IMAGEM ENVIADA (identificação) | C1: CÓDIGO CANDIDATO | D1: DESCRIÇÃO NA LISTA | E1: FABRICANTE | F1: SALDO | G1: É ESTE? (marque X)
B2: BOTINA DE SEGURANÇA COM CADARÇO PRETA | C2: 053998 | D2: BOTINA AMA 3 G NOBUCK CAFE 38 S BICO BI TP092 CARTON | E2: CARTON | F2: 1
C3: 054818 | D3: BOTINA AMARRAR NOBUCK PRETA 39 S BICO BI TP200P CARTON | E3: CARTON | F3: 1
C4: 054819 | D4: BOTINA AMARRAR NOBUCK PRETA 40 S BICO BI TP200P CARTON | E4: CARTON | F4: 1
C5: 054820 | D5: BOTINA AMARRAR NOBUCK PRETA 41 S BICO BI TP200P CARTON | E5: CARTON | F5: 1
C6: 054832 | D6: BOTINA AMARRAR 3 GOMOS 39 S BICO BI MOD20 CARTON | E6: CARTON | F6: 1
C7: 054835 | D7: BOTINA AMARRAR 3 GOMOS 42 S BICO BI MOD20 CARTON | E7: CARTON | F7: 1
C8: 054836 | D8: BOTINA AMARRAR 3 GOMOS 43 S BICO BI MOD20 CARTON | E8: CARTON | F8: 1
C9: 053773 | D9: BOTINA AMA 3 G NOBUCK CAFE 43 S BICO BI TP092 CARTON | E9: CARTON | F9: 2
C10: 054007 | D10: BOTINA AMA 3 G NOBUCK CAFE 45 S BICO BI TP092 CARTON | E10: CARTON | F10: 2
C11: 054823 | D11: BOTINA AMARRAR NOBUCK PRETA 44 S BICO BI TP200P CARTON | E11: CARTON | F11: 2
C12: 053470 | D12: BOTINA AMA 3 G NOBUCK CAFE 40 S BICO BI TP092 CARTON | E12: CARTON | F12: 3
C13: 053471 | D13: BOTINA AMA 3 G NOBUCK CAFE 41 S BICO BI TP092 CARTON | E13: CARTON | F13: 3
C14: 053472 | D14: BOTINA AMA 3 G NOBUCK CAFE 42 S BICO BI TP092 CARTON | E14: CARTON | F14: 3
... C16: 054822 | D16: BOTINA AMARRAR NOBUCK PRETA 43 S BICO BI TP200P CARTON | E16: CARTON | F16: 3
B17: BOTINA DE SEGURANÇA COM ELÁSTICO PRETA | C17: 053459 | D17: BOTINA ELESTICO BIDENSIDADE SEM BICO 39 MOD10 CARTON | E17: CARTON | F17: 1
C18: 053457 | D18: BOTINA ELESTICO BIDENSIDADE SEM BICO 38 MOD10 CARTON | E18: CARTON | F18: 2
C19: 053468 | D19: BOTINA ELESTICO BIDENSIDADE COM BICO PVC 44 TP080 CARTON | E19: CARTON | F19: 2
C20: 053469 | D20: BOTINA ELESTICO BIDENSIDADE SEM BICO 44 MOD10 CARTON | E20: CARTON | F20: 6
B21: CONTATOR 1 POLO 25A 220V FACON | C21: 052872 | D21: CONTATOR ELETROMAGNETICO 220V TRIF 25A WEG | F21: 1
C22: 054421 | D22: CONTATOR 25A NC1-2510 220V 50/60HZ - CHINT REF: 925735 | E22: CHINT | F22: 28
B23: KTM 1000 (PEÇA PLÁSTICA BRANCA) | D23: Nenhum candidato encontrado na lista
B24: PROTETOR CONTRA SURTOS DE TOMADA (PLUGUE 2P+T) | C24: 055058 | D24: DPS DISPOSITIVO DE PROTECAO CONTRA SURTO 20KA 127V CLASSE II | E24: MARGIRIUS | F24: 3
C25: 055099 | D25: DPS DISPOSITIVO DE PROTECAO CONTRA SURTO 45KA 127V CLASSE II | E25: MARGIRIUS | F25: 4
C26: 055100 | D26: DPS DISPOSITIVO DE PROTECAO CONTRA SURTO 60KA 127V CLASSE II | E26: MARGIRIUS | F26: 4
C27: 055835 | D27: PROTETOR RAIO SUPER 127V PW | E27: PW | F27: 4
C28: 055097 | D28: DPS DISPOSITIVO DE PROTECAO CONTRA SURTO 12KA 127V CLASSE II | E28: MARGIRIUS | F28: 5
C29: 053980 | D29: DPS VCL 275V 45KA SLIM DISPOSIT D PROTECAO CONTRA SURTOS ELE | E29: CLAMPER INDUSTRIA E COMERCIO S | F29: 6
C30: 055098 | D30: DPS DISPOSITIVO DE PROTECAO CONTRA SURTO 30KA 127V CLASSE II | E30: MARGIRIUS | F30: 8
C31: 055833 | D31: PROTETOR RAIO ELETRO 2 TOMADAS 10A 127V PW | E31: PW | F31: 8
C32: 055836 | D32: PROTETOR RAIO ELETRO 2 TOMADAS 20A BIVOLT PW | E32: PW | F32: 24
C33: 055834 | D33: PROTETOR RAIO GELADEIRA E FREEZER 127V PW | E33: PW | F33: 31
C34: 055063 | D34: PROTETOR DE EQUIP ELETR CONTRA SURTO DE TENSAO PEE-4K5 | E34: MARGIRIUS | F34: 35
C35: 059232 | D35: PROTETOR RAIO LAVADORA 10A 127V | E35: PW | F35: 46
B36: SENSOR DE TEMPERATURA COM BULBO DE COBRE P/ AR CONDICIONADO | C36: 051838 | D36: SENSOR DEG AR COND 20K 7-9-12-18-24-30K PANASONIC | F36: 2
C37: 053971 | D37: REDE ELECTROLUX C SENSOR DEGELO DF80/DF80X/DF38/DW42X/DFI80 | E37: SAMATEC | F37: 2
C38: 054910 | D38: REDE SENSOR/DEGELO REFR ELECTROLUX DF80/DFI80 41019315 | E38: ELECTROLUX | F38: 2
C39: 052486 | D39: SENSOR DE DEGELO 10K PARA A/C FACON | E39: FACON | F39: 3
C40: 053190 | D40: REDE ELECTROLUX C SENSOR DEGELO DF80/DFI80 41003635 | E40: ELECTROLUX | F40: 3
C41: 057515 | D41: SENSOR SERPENTINDA DEGELO EVAP 10K | E41: MIGRARE | F41: 3
...

Sheet RESUMO
A1: CATEGORIA | B1: Nº DE ITENS | C1: COM FOTO | D1: SEM FOTO | E1: % COM FOTO | F1: SALDO SEM FOTO
A2: Automação / Temporizadores | B2: =COUNTIF(PRODUTOS!$I$2:$I$3264,A2) -> 72 | C2: =COUNTIFS(PRODUTOS!$I$2:$I$3264,A2,PRODUTOS!$H$2:$H$3264,"COM FOTO")+COUNTIFS(PRODUTOS!$I$2:$I$3264,A2,PRODUTOS!$H$2:$H$3264,"FOTO DE PRODUTO EQUIVALENTE") -> 5 | D2: =B2-C2 -> 67 | E2: =IF(B2=0,0,C2/B2) -> 0.069444444 | F2: =SUMIFS(PRODUTOS!$G$2:$G$3264,PRODUTOS!$I$2:$I$3264,A2,PRODUTOS!$H$2:$H$3264,"SEM FOTO")+SUMIFS(PRODUTOS!$G$2:$G$3264,PRODUTOS!$I$2:$I$3264,A2,PRODUTOS!$H$2:$H$3264,"FOTO NÃO CONFERE") -> 812
A3: Capacitores | B3: =COUNTIF(PRODUTOS!$I$2:$I$3264,A3) -> 204 | C3: =COUNTIFS(PRODUTOS!$I$2:$I$3264,A3,PRODUTOS!$H$2:$H$3264,"COM FOTO")+COUNTIFS(PRODUTOS!$I$2:$I$3264,A3,PRODUTOS!$H$2:$H$3264,"FOTO DE PRODUTO EQUIVALENTE") -> 64 | D3: =B3-C3 -> 140 | E3: =IF(B3=0,0,C3/B3) -> 0.31372549 | F3: =SUMIFS(PRODUTOS!$G$2:$G$3264,PRODUTOS!$I$2:$I$3264,A3,PRODUTOS!$H$2:$H$3264,"SEM FOTO")+SUMIFS(PRODUTOS!$G$2:$G$3264,PRODUTOS!$I$2:$I$3264,A3,PRODUTOS!$H$2:$H$3264,"FOTO NÃO CONFERE") -> 8209
A4: EPI / Segurança | B4: =COUNTIF(PRODUTOS!$I$2:$I$3264,A4) -> 117 | C4: =COUNTIFS(PRODUTOS!$I$2:$I$3264,A4,PRODUTOS!$H$2:$H$3264,"COM FOTO")+COUNTIFS(PRODUTOS!$I$2:$I$3264,A4,PRODUTOS!$H$2:$H$3264,"FOTO DE PRODUTO EQUIVALENTE") -> 16 | D4: =B4-C4 -> 101 | E4: =IF(B4=0,0,C4/B4) -> 0.13675214 | F4: =SUMIFS(PRODUTOS!$G$2:$G$3264,PRODUTOS!$I$2:$I$3264,A4,PRODUTOS!$H$2:$H$3264,"SEM FOTO")+SUMIFS(PRODUTOS!$G$2:$G$3264,PRODUTOS!$I$2:$I$3264,A4,PRODUTOS!$H$2:$H$3264,"FOTO NÃO CONFERE") -> 7329
A5: Eletrônicos / Informática | B5: =COUNTIF(PRODUTOS!$I$2:$I$3264,A5) -> 81 | C5: =COUNTIFS(PRODUTOS!$I$2:$I$3264,A5,PRODUTOS!$H$2:$H$3264,"COM FOTO")+COUNTIFS(PRODUTOS!$I$2:$I$3264,A5,PRODUTOS!$H$2:$H$3264,"FOTO DE PRODUTO EQUIVALENTE") -> 0 | D5: =B5-C5 -> 81 | E5: =IF(B5=0,0,C5/B5) -> 0 | F5: =SUMIFS(PRODUTOS!$G$2:$G$3264,PRODUTOS!$I$2:$I$3264,A5,PRODUTOS!$H$2:$H$3264,"SEM FOTO")+SUMIFS(PRODUTOS!$G$2:$G$3264,PRODUTOS!$I$2:$I$3264,A5,PRODUTOS!$H$2:$H$3264,"FOTO NÃO CONFERE") -> 943
A6: Elétrica / Comandos | B6: =COUNTIF(PRODUTOS!$I$2:$I$3264,A6) -> 575 | C6: =COUNTIFS(PRODUTOS!$I$2:$I$3264,A6,PRODUTOS!$H$2:$H$3264,"COM FOTO")+COUNTIFS(PRODUTOS!$I$2:$I$3264,A6,PRODUTOS!$H$2:$H$3264,"FOTO DE PRODUTO EQUIVALENTE") -> 33 | D6: =B6-C6 -> 542 | E6: =IF(B6=0,0,C6/B6) -> 0.057391304 | F6: =SUMIFS(PRODUTOS!$G$2:$G$3264,PRODUTOS!$I$2:$I$3264,A6,PRODUTOS!$H$2:$H$3264,"SEM FOTO")+SUMIFS(PRODUTOS!$G$2:$G$3264,PRODUTOS!$I$2:$I$3264,A6,PRODUTOS!$H$2:$H$3264,"FOTO NÃO CONFERE") -> 120794.7
A7: Ferramentas / Instrumentos | B7: =COUNTIF(PRODUTOS!$I$2:$I$3264,A7) -> 528 | C7: =COUNTIFS(PRODUTOS!$I$2:$I$3264,A7,PRODUTOS!$H$2:$H$3264,"COM FOTO")+COUNTIFS(PRODUTOS!$I$2:$I$3264,A7,PRODUTOS!$H$2:$H$3264,"FOTO DE PRODUTO EQUIVALENTE") -> 3 | D7: =B7-C7 -> 525 | E7: =IF(B7=0,0,C7/B7) -> 0.0056818182 | F7: =SUMIFS(PRODUTOS!$G$2:$G$3264,PRODUTOS!$I$2:$I$3264,A7,PRODUTOS!$H$2:$H$3264,"SEM FOTO")+SUMIFS(PRODUTOS!$G$2:$G$3264,PRODUTOS!$I$2:$I$3264,A7,PRODUTOS!$H$2:$H$3264,"FOTO NÃO CONFERE") -> 16760
A8: Filtros e Purificadores de Água | B8: =COUNTIF(PRODUTOS!$I$2:$I$3264,A8) -> 35 | C8: =COUNTIFS(PRODUTOS!$I$2:$I$3264,A8,PRODUTOS!$H$2:$H$3264,"COM FOTO")+COUNTIFS(PRODUTOS!$I$2:$I$3264,A8,PRODUTOS!$H$2:$H$3264,"FOTO DE PRODUTO EQUIVALENTE") -> 10 | D8: =B8-C8 -> 25 | E8: =IF(B8=0,0,C8/B8) -> 0.28571429 | F8: =SUMIFS(PRODUTOS!$G$2:$G$3264,PRODUTOS!$I$2:$I$3264,A8,PRODUTOS!$H$2:$H$3264,"SEM FOTO")+SUMIFS(PRODUTOS!$G$2:$G$3264,PRODUTOS!$I$2:$I$3264,A8,PRODUTOS!$H$2:$H$3264,"FOTO NÃO CONFERE") -> 213
A9: Fixação e Acessórios | B9: =COUNTIF(PRODUTOS!$I$2:$I$3264,A9) -> 190 | C9: =COUNTIFS(PRODUTOS!$I$2:$I$3264,A9,PRODUTOS!$H$2:$H$3264,"COM FOTO")+COUNTIFS(PRODUTOS!$I$2:$I$3264,A9,PRODUTOS!$H$2:$H$3264,"FOTO DE PRODUTO EQUIVALENTE") -> 0 | D9: =B9-C9 -> 190 | E9: =IF(B9=0,0,C9/B9) -> 0 | F9: =SUMIFS(PRODUTOS!$G$2:$G$3264,PRODUTOS!$I$2:$I$3264,A9,PRODUTOS!$H$2:$H$3264,"SEM FOTO")+SUMIFS(PRODUTOS!$G$2:$G$3264,PRODUTOS!$I$2:$I$3264,A9,PRODUTOS!$H$2:$H$3264,"FOTO NÃO CONFERE") -> 75983
A10: Gases Refrigerantes | B10: =COUNTIF(PRODUTOS!$I$2:$I$3264,A10) -> 147 | C10: =COUNTIFS(PRODUTOS!$I$2:$I$3264,A10,PRODUTOS!$H$2:$H$3264,"COM FOTO")+COUNTIFS(PRODUTOS!$I$2:$I$3264,A10,PRODUTOS!$H$2:$H$3264,"FOTO DE PRODUTO EQUIVALENTE") -> 0 | D10: =B10-C10 -> 147 | E10: =IF(B10=0,0,C10/B10) -> 0 | F10: =SUMIFS(PRODUTOS!$G$2:$G$3264,PRODUTOS!$I$2:$I$3264,A10,PRODUTOS!$H$2:$H$3264,"SEM FOTO")+SUMIFS(PRODUTOS!$G$2:$G$3264,PRODUTOS!$I$2:$I$3264,A10,PRODUTOS!$H$2:$H$3264,"FOTO NÃO CONFERE") -> 3704.647
A11: Hidráulica | B11: =COUNTIF(PRODUTOS!$I$2:$I$3264,A11) -> 54 | C11: =COUNTIFS(PRODUTOS!$I$2:$I$3264,A11,PRODUTOS!$H$2:$H$3264,"COM FOTO")+COUNTIFS(PRODUTOS!$I$2:$I$3264,A11,PRODUTOS!$H$2:$H$3264,"FOTO DE PRODUTO EQUIVALENTE") -> 0 | D11: =B11-C11 -> 54 | E11: =IF(B11=0,0,C11/B11) -> 0 | F11: =SUMIFS(PRODUTOS!$G$2:$G$3264,PRODUTOS!$I$2:$I$3264,A11,PRODUTOS!$H$2:$H$3264,"SEM FOTO")+SUMIFS(PRODUTOS!$G$2:$G$3264,PRODUTOS!$I$2:$I$3264,A11,PRODUTOS!$H$2:$H$3264,"FOTO NÃO CONFERE") -> 4971
A12: Iluminação | B12: =COUNTIF(PRODUTOS!$I$2:$I$3264,A12) -> 199 | C12: =COUNTIFS(PRODUTOS!$I$2:$I$3264,A12,PRODUTOS!$H$2:$H$3264,"COM FOTO")+COUNTIFS(PRODUTOS!$I$2:$I$3264,A12,PRODUTOS!$H$2:$H$3264,"FOTO DE PRODUTO EQUIVALENTE") -> 0 | D12: =B12-C12 -> 199 | E12: =IF(B12=0,0,C12/B12) -> 0 | F12: =SUMIFS(PRODUTOS!$G$2:$G$3264,PRODUTOS!$I$2:$I$3264,A12,PRODUTOS!$H$2:$H$3264,"SEM FOTO")+SUMIFS(PRODUTOS!$G$2:$G$3264,PRODUTOS!$I$2:$I$3264,A12,PRODUTOS!$H$2:$H$3264,"FOTO NÃO CONFERE") -> 8675
A13: Instalação de Ar-Condicionado | B13: =COUNTIF(PRODUTOS!$I$2:$I$3264,A13) -> 205 | C13: =COUNTIFS(PRODUTOS!$I$2:$I$3264,A13,PRODUTOS!$H$2:$H$3264,"COM FOTO")+COUNTIFS(PRODUTOS!$I$2:$I$3264,A13,PRODUTOS!$H$2:$H$3264,"FOTO DE PRODUTO EQUIVALENTE") -> 1 | D13: =B13-C13 -> 204 | E13: =IF(B13=0,0,C13/B13) -> 0.0048780488 | F13: =SUMIFS(PRODUTOS!$G$2:$G$3264,PRODUTOS!$I$2:$I$3264,A13,PRODUTOS!$H$2:$H$3264,"SEM FOTO")+SUMIFS(PRODUTOS!$G$2:$G$3264,PRODUTOS!$I$2:$I$3264,A13,PRODUTOS!$H$2:$H$3264,"FOTO NÃO CONFERE") -> 20069.434
... A17: Refrigeração / Componentes | B17: =COUNTIF(PRODUTOS!$I$2:$I$3264,A17) -> 392 | C17: =COUNTIFS(PRODUTOS!$I$2:$I$3264,A17,PRODUTOS!$H$2:$H$3264,"COM FOTO")+COUNTIFS(PRODUTOS!$I$2:$I$3264,A17,PRODUTOS!$H$2:$H$3264,"FOTO DE PRODUTO EQUIVALENTE") -> 29 | D17: =B17-C17 -> 363 | E17: =IF(B17=0,0,C17/B17) -> 0.073979592 | F17: =SUMIFS(PRODUTOS!$G$2:$G$3264,PRODUTOS!$I$2:$I$3264,A17,PRODUTOS!$H$2:$H$3264,"SEM FOTO")+SUMIFS(PRODUTOS!$G$2:$G$3264,PRODUTOS!$I$2:$I$3264,A17,PRODUTOS!$H$2:$H$3264,"FOTO NÃO CONFERE") -> 19804.5
A18: TOTAL | B18: =SUM(B2:B17) -> 3263 | C18: =SUM(C2:C17) -> 171 | D18: =SUM(D2:D17) -> 3092 | E18: =IF(B18=0,0,C18/B18) -> 0.052405762 | F18: =SUM(F2:F17) -> 303695.66
A20: Itens com foto pelo código | B20: =COUNTIF(PRODUTOS!$H$2:$H$3264,"COM FOTO") -> 169
A21: Itens com foto de produto equivalente (conferir) | B21: =COUNTIF(PRODUTOS!$H$2:$H$3264,"FOTO DE PRODUTO EQUIVALENTE") -> 2
A22: Itens em que a foto do catálogo NÃO confere | B22: =COUNTIF(PRODUTOS!$H$2:$H$3264,"FOTO NÃO CONFERE") -> 1
A23: Divergências (sem contar informativas) | B23: =COUNTIF(DIVERGÊNCIAS!$C$2:$C$114,"<>*informativo*") -> 46
A24: Produtos do catálogo fora da lista | B24: =COUNTA('CATÁLOGO FORA DA LISTA'!$C$2:$C$147) -> 146
A26: Fonte: LISTAPRODUTO_LOJA01_ARISTEU_REFRIGERAÇÃO.xls (lista do sistema) cruzada com o catálogo PDF e as imagens enviadas. SALDO = quantidade em estoque informada na planilha.

Sheet LEIA-ME
A1: O QUE É | B1: Sua lista de produtos (LISTAPRODUTO_LOJA01_ARISTEU_REFRIGERAÇÃO.xls) com a foto tratada de cada item que existe no catálogo, além das divergências encontradas entre a lista e o catálogo.
A2: IMAGEM | B2: Miniatura 30x30 px antes do código. Acompanha a linha ao filtrar/ordenar. A foto em alta está na pasta png_transparente_1200 com o nome = código.
A3: STATUS DA FOTO | B3: COM FOTO: mesmo código do catálogo (ou item sem código no catálogo conferido pela descrição/referência) · FOTO DE PRODUTO EQUIVALENTE: descrição igual a outro item do catálogo — conferir · FOTO NÃO CONFERE: o catálogo usa o código, mas a marca é outra; a foto não foi usada · SEM FOTO: buscar no site do fabricante (aba SEM FOTO).
A4: REFERÊNCIA / MARCA | B4: Valem as da sua planilha. Quando vazias, foram completadas com o catálogo (marcado como informativo). Diferenças aparecem em DIVERGÊNCIAS.
A5: INFORMAÇÕES COMPLEMENTARES | B5: Vêm do catálogo (medidas, aplicações, compatibilidades) para os itens com foto. Conferir a ficha do fornecedor antes de publicar especificações críticas.
A6: SEM FOTO (BUSCAR) | B6: Itens sem foto ordenados pelo SALDO (mais estoque primeiro) com um termo de busca pronto. Com a rede do ambiente liberada, as fotos podem ser buscadas nos sites dos fabricantes.
A7: DIVERGÊNCIAS | B7: Marca diferente, descrição diferente para o mesmo código, código repetido no catálogo, referência diferente, descrições iguais com códigos diferentes (possível cadastro duplicado).
A8: CATÁLOGO FORA DA LISTA | B8: Produtos do catálogo que não estão na sua lista (a lista traz só itens com saldo). Quando existe um item parecido na lista, o código provável aparece ao lado.
A9: IMAGENS ENVIADAS | B9: Fotos enviadas sem código: marque com X o código correto para que a foto seja vinculada na próxima geração.
